Workbook

Sheet PREDVOLBY
B2: Předvolby výkazu — evidence pracovní doby 2027
B3: Dodio · správa firemních absencí na pár kliknutí
B5: Zaměstnanec
B6: Jméno a příjmení | C6: Jméno a příjmení | D6: Zobrazí se v záhlaví každého měsíce.
B7: Společnost | C7: Název společnosti | D7: Zobrazí se v záhlaví každého měsíce.
B8: Rok evidence | C8: 2027 | D8: Pevně dáno názvy listů (01_2027 – 12_2027).
B10: Dovolená a limity
B11: Převod dovolené z loňského roku (dny) | C11: 0 | D11: Nevyčerpané dny převedené z roku 2026.
B12: Roční fond dovolené (dny) | C12: 30 | D12: Hodnota převzata ze vzoru 2026 — upravte dle smlouvy.
B13: Celkem dní k čerpání dovolené | C13: =$C$12+$C$11 -> 30 | D13: Vypočítá se automaticky.
B14: Limit Home Office (dny / rok) | C14: 25 | D14: Hodnota převzata ze vzoru 2026.
B15: Limit Sick Day (dny / rok) | C15: 5 | D15: Ve vzoru 2026 40 hodin = 5 dní po 8 h.
B17: Pracovní doba (výchozí pro všechny dny)
B18: Začátek práce | C18: 0.3125 | D18: Předvyplní sloupec „od“ v 1. bloku.
B19: Konec 1. bloku (začátek přestávky) | C19: 0.47916667
B20: Začátek 2. bloku (konec přestávky) | C20: 0.5
B21: Konec práce | C21: 0.66666667
B22: Denní fond pracovní doby (hodiny) | C22: =ROUND(((C19-C18)+(C21-C20))*24,2) -> 8 | D22: Vypočítá se z časů výše (vzor: 8 h).
B24: Stravné
B25: Stravenkový paušál (Kč / den) | C25: 129.5 | D25: Hodnota převzata ze vzoru 2026 — aktualizujte dle sazby pro rok 2027.
B26: Nárok na stravné od (odpracované hodiny) | C26: 3 | D26: Vzor: nárok po odpracování 3 hodin.
B28: Legenda: žlutě podbarvené buňky s modrým písmem jsou vstupy k vyplnění. Ostatní hodnoty se dopočítávají a není třeba je měnit. Státní svátky jsou na listu SVATKY_2027.
B32: Bezplatná šablona Dodio

Sheet SVATKY_2027
B2: Státní svátky 2027
B3: Dodio · správa firemních absencí na pár kliknutí
B4: Datum | C4: Svátek | D4: Den
B5: 46388 | C5: Nový rok / Den obnovy samostatného českého státu | D5: =IF(B5="","",CHOOSE(WEEKDAY(B5,2),"pondělí","úterý","středa","čtvrtek","pátek","sobota","neděle")) -> pátek
B6: 46472 | C6: Velký pátek | D6: =IF(B6="","",CHOOSE(WEEKDAY(B6,2),"pondělí","úterý","středa","čtvrtek","pátek","sobota","neděle")) -> pátek
B7: 46475 | C7: Velikonoční pondělí | D7: =IF(B7="","",CHOOSE(WEEKDAY(B7,2),"pondělí","úterý","středa","čtvrtek","pátek","sobota","neděle")) -> pondělí
B8: 46508 | C8: Svátek práce | D8: =IF(B8="","",CHOOSE(WEEKDAY(B8,2),"pondělí","úterý","středa","čtvrtek","pátek","sobota","neděle")) -> sobota
B9: 46515 | C9: Den vítězství | D9: =IF(B9="","",CHOOSE(WEEKDAY(B9,2),"pondělí","úterý","středa","čtvrtek","pátek","sobota","neděle")) -> sobota
B10: 46573 | C10: Den slovanských věrozvěstů Cyrila a Metoděje | D10: =IF(B10="","",CHOOSE(WEEKDAY(B10,2),"pondělí","úterý","středa","čtvrtek","pátek","sobota","neděle")) -> pondělí
B11: 46574 | C11: Den upálení mistra Jana Husa | D11: =IF(B11="","",CHOOSE(WEEKDAY(B11,2),"pondělí","úterý","středa","čtvrtek","pátek","sobota","neděle")) -> úterý
B12: 46658 | C12: Den české státnosti | D12: =IF(B12="","",CHOOSE(WEEKDAY(B12,2),"pondělí","úterý","středa","čtvrtek","pátek","sobota","neděle")) -> úterý
B13: 46688 | C13: Den vzniku samostatného československého státu | D13: =IF(B13="","",CHOOSE(WEEKDAY(B13,2),"pondělí","úterý","středa","čtvrtek","pátek","sobota","neděle")) -> čtvrtek
B14: 46708 | C14: Den boje za svobodu a demokracii | D14: =IF(B14="","",CHOOSE(WEEKDAY(B14,2),"pondělí","úterý","středa","čtvrtek","pátek","sobota","neděle")) -> středa
B15: 46745 | C15: Štědrý den | D15: =IF(B15="","",CHOOSE(WEEKDAY(B15,2),"pondělí","úterý","středa","čtvrtek","pátek","sobota","neděle")) -> pátek
B16: 46746 | C16: 1. svátek vánoční | D16: =IF(B16="","",CHOOSE(WEEKDAY(B16,2),"pondělí","úterý","středa","čtvrtek","pátek","sobota","neděle")) -> sobota
B17: 46747 | C17: 2. svátek vánoční | D17: =IF(B17="","",CHOOSE(WEEKDAY(B17,2),"pondělí","úterý","středa","čtvrtek","pátek","sobota","neděle")) -> neděle
D18: =IF(B18="","",CHOOSE(WEEKDAY(B18,2),"pondělí","úterý","středa","čtvrtek","pátek","sobota","neděle"))
D19: =IF(B19="","",CHOOSE(WEEKDAY(B19,2),"pondělí","úterý","středa","čtvrtek","pátek","sobota","neděle"))
D20: =IF(B20="","",CHOOSE(WEEKDAY(B20,2),"pondělí","úterý","středa","čtvrtek","pátek","sobota","neděle"))
D21: =IF(B21="","",CHOOSE(WEEKDAY(B21,2),"pondělí","úterý","středa","čtvrtek","pátek","sobota","neděle"))
D22: =IF(B22="","",CHOOSE(WEEKDAY(B22,2),"pondělí","úterý","středa","čtvrtek","pátek","sobota","neděle"))
B24: Volné řádky lze použít pro firemní volno (např. „sick day“ celé firmy). Každé datum v seznamu se v měsíčních listech automaticky označí jako svátek. Velikonoce 2027: neděle 28. 3. (Velký pátek 26. 3., Velikonoční pondělí 29. 3.).
B27: Bezplatná šablona Dodio

Sheet 01_2027
A1: EVIDENCE PRACOVNÍ DOBY 2027 | N1: Dodio · správa firemních absencí na pár kliknutí
A2: =IF(PREDVOLBY!$C$7="","",PREDVOLBY!$C$7) -> Název společnosti
A3: OBDOBÍ | C3: Leden 2027 | G3: JMÉNO: | I3: =IF(OR(PREDVOLBY!$C$6="",PREDVOLBY!$C$6="Jméno a příjmení"),"DOPLŇTE ÚDAJE V KARTĚ PŘEDVOLBY",PREDVOLBY!$C$6) -> DOPLŇTE ÚDAJE V KARTĚ PŘEDVOLBY | U3: 46388
A4: Den | B4: dne | C4: pracovní doba | E4: pracovní doba | G4: odpracováno celkem (h) | H4: z toho přesčas (h) | I4: stravné (Kč) | J4: SC / pracovní oběd / TMB | K4: neodpracované hodiny z důvodu | Q4: Home Office | R4: Sick Day | S4: Poznámka | U4: pomocné sloupce (skryté)
C5: od | D5: do | E5: od | F5: do | K5: D | L5: N | M5: S | N5: § | O5: NV | P5: NEP | U5: typ dne | V5: podíl nepřítomnosti
A6: =IF(MONTH(DATE(PREDVOLBY!$C$8,1,1))=1,DATE(PREDVOLBY!$C$8,1,1),"") -> 46388 | B6: =IF($A6="","",CHOOSE(WEEKDAY($A6,2),"po","út","st","čt","pá","so","ne")) -> pá | C6: =IF(OR($A6="",$U6="Víkend"),"",IF($V6>=1,"-",PREDVOLBY!$C$18)) -> - | D6: =IF(OR($A6="",$U6="Víkend"),"",IF($V6>=1,"-",PREDVOLBY!$C$19)) -> - | E6: =IF(OR($A6="",$U6="Víkend"),"",IF($V6>=0.5,"-",PREDVOLBY!$C$20)) -> - | F6: =IF(OR($A6="",$U6="Víkend"),"",IF($V6>=0.5,"-",PREDVOLBY!$C$21)) -> - | G6: =IF(OR($A6="",$U6="Víkend"),"",IF(ISNUMBER($C6)+ISNUMBER($E6)=0,"-",ROUND((IF(ISNUMBER($C6),$D6-$C6,0)+IF(ISNUMBER($E6),$F6-$E6,0))*24,2))) -> - | H6: =IF($G6="","",IF(ISNUMBER($G6),MAX(0,ROUND($G6-PREDVOLBY!$C$22*(1-$V6),2)),"-")) -> - | I6: =IF($G6="","",IF(AND(ISNUMBER($G6),$J6=""),IF($G6>=PREDVOLBY!$C$26,PREDVOLBY!$C$25,"-"),"-")) -> - | M6: =IF($U6="Svátek",1,"") -> 1 | S6: =IF($U6="Svátek",IFERROR(INDEX(SVATKY_2027!$C$5:$C$22,MATCH($A6,SVATKY_2027!$B$5:$B$22,0)),""),"") -> Nový rok / Den obnovy samostatného českého státu | U6: =IF($A6="","",IF(WEEKDAY($A6,2)>5,"Víkend",IF(COUNTIF(SVATKY_2027!$B$5:$B$22,$A6)>0,"Svátek",""))) -> Svátek | V6: =IF(OR($A6="",$U6="Víkend"),0,IF($U6="Svátek",1,MIN(1,COUNTIF($K6:$P6,"x")+COUNTIF($K6:$P6,1)+0.5*COUNTIF($K6:$P6,0.5)+IF(OR($R6="x",$R6=1),1,IF($R6=0.5,0.5,0))))) -> 1
A7: =IF(MONTH(DATE(PREDVOLBY!$C$8,1,2))=1,DATE(PREDVOLBY!$C$8,1,2),"") -> 46389 | B7: =IF($A7="","",CHOOSE(WEEKDAY($A7,2),"po","út","st","čt","pá","so","ne")) -> so | C7: =IF(OR($A7="",$U7="Víkend"),"",IF($V7>=1,"-",PREDVOLBY!$C$18)) | D7: =IF(OR($A7="",$U7="Víkend"),"",IF($V7>=1,"-",PREDVOLBY!$C$19)) | E7: =IF(OR($A7="",$U7="Víkend"),"",IF($V7>=0.5,"-",PREDVOLBY!$C$20)) | F7: =IF(OR($A7="",$U7="Víkend"),"",IF($V7>=0.5,"-",PREDVOLBY!$C$21)) | G7: =IF(OR($A7="",$U7="Víkend"),"",IF(ISNUMBER($C7)+ISNUMBER($E7)=0,"-",ROUND((IF(ISNUMBER($C7),$D7-$C7,0)+IF(ISNUMBER($E7),$F7-$E7,0))*24,2))) | H7: =IF($G7="","",IF(ISNUMBER($G7),MAX(0,ROUND($G7-PREDVOLBY!$C$22*(1-$V7),2)),"-")) | I7: =IF($G7="","",IF(AND(ISNUMBER($G7),$J7=""),IF($G7>=PREDVOLBY!$C$26,PREDVOLBY!$C$25,"-"),"-")) | M7: =IF($U7="Svátek",1,"") | S7: =IF($U7="Svátek",IFERROR(INDEX(SVATKY_2027!$C$5:$C$22,MATCH($A7,SVATKY_2027!$B$5:$B$22,0)),""),"") | U7: =IF($A7="","",IF(WEEKDAY($A7,2)>5,"Víkend",IF(COUNTIF(SVATKY_2027!$B$5:$B$22,$A7)>0,"Svátek",""))) -> Víkend | V7: =IF(OR($A7="",$U7="Víkend"),0,IF($U7="Svátek",1,MIN(1,COUNTIF($K7:$P7,"x")+COUNTIF($K7:$P7,1)+0.5*COUNTIF($K7:$P7,0.5)+IF(OR($R7="x",$R7=1),1,IF($R7=0.5,0.5,0))))) -> 0
A8: =IF(MONTH(DATE(PREDVOLBY!$C$8,1,3))=1,DATE(PREDVOLBY!$C$8,1,3),"") -> 46390 | B8: =IF($A8="","",CHOOSE(WEEKDAY($A8,2),"po","út","st","čt","pá","so","ne")) -> ne | C8: =IF(OR($A8="",$U8="Víkend"),"",IF($V8>=1,"-",PREDVOLBY!$C$18)) | D8: =IF(OR($A8="",$U8="Víkend"),"",IF($V8>=1,"-",PREDVOLBY!$C$19)) | E8: =IF(OR($A8="",$U8="Víkend"),"",IF($V8>=0.5,"-",PREDVOLBY!$C$20)) | F8: =IF(OR($A8="",$U8="Víkend"),"",IF($V8>=0.5,"-",PREDVOLBY!$C$21)) | G8: =IF(OR($A8="",$U8="Víkend"),"",IF(ISNUMBER($C8)+ISNUMBER($E8)=0,"-",ROUND((IF(ISNUMBER($C8),$D8-$C8,0)+IF(ISNUMBER($E8),$F8-$E8,0))*24,2))) | H8: =IF($G8="","",IF(ISNUMBER($G8),MAX(0,ROUND($G8-PREDVOLBY!$C$22*(1-$V8),2)),"-")) | I8: =IF($G8="","",IF(AND(ISNUMBER($G8),$J8=""),IF($G8>=PREDVOLBY!$C$26,PREDVOLBY!$C$25,"-"),"-")) | M8: =IF($U8="Svátek",1,"") | S8: =IF($U8="Svátek",IFERROR(INDEX(SVATKY_2027!$C$5:$C$22,MATCH($A8,SVATKY_2027!$B$5:$B$22,0)),""),"") | U8: =IF($A8="","",IF(WEEKDAY($A8,2)>5,"Víkend",IF(COUNTIF(SVATKY_2027!$B$5:$B$22,$A8)>0,"Svátek",""))) -> Víkend | V8: =IF(OR($A8="",$U8="Víkend"),0,IF($U8="Svátek",1,MIN(1,COUNTIF($K8:$P8,"x")+COUNTIF($K8:$P8,1)+0.5*COUNTIF($K8:$P8,0.5)+IF(OR($R8="x",$R8=1),1,IF($R8=0.5,0.5,0))))) -> 0
A9: =IF(MONTH(DATE(PREDVOLBY!$C$8,1,4))=1,DATE(PREDVOLBY!$C$8,1,4),"") -> 46391 | B9: =IF($A9="","",CHOOSE(WEEKDAY($A9,2),"po","út","st","čt","pá","so","ne")) -> po | C9: =IF(OR($A9="",$U9="Víkend"),"",IF($V9>=1,"-",PREDVOLBY!$C$18)) -> 0.3125 | D9: =IF(OR($A9="",$U9="Víkend"),"",IF($V9>=1,"-",PREDVOLBY!$C$19)) -> 0.47916667 | E9: =IF(OR($A9="",$U9="Víkend"),"",IF($V9>=0.5,"-",PREDVOLBY!$C$20)) -> 0.5 | F9: =IF(OR($A9="",$U9="Víkend"),"",IF($V9>=0.5,"-",PREDVOLBY!$C$21)) -> 0.66666667 | G9: =IF(OR($A9="",$U9="Víkend"),"",IF(ISNUMBER($C9)+ISNUMBER($E9)=0,"-",ROUND((IF(ISNUMBER($C9),$D9-$C9,0)+IF(ISNUMBER($E9),$F9-$E9,0))*24,2))) -> 8 | H9: =IF($G9="","",IF(ISNUMBER($G9),MAX(0,ROUND($G9-PREDVOLBY!$C$22*(1-$V9),2)),"-")) -> 0 | I9: =IF($G9="","",IF(AND(ISNUMBER($G9),$J9=""),IF($G9>=PREDVOLBY!$C$26,PREDVOLBY!$C$25,"-"),"-")) -> 129.5 | M9: =IF($U9="Svátek",1,"") | S9: =IF($U9="Svátek",IFERROR(INDEX(SVATKY_2027!$C$5:$C$22,MATCH($A9,SVATKY_2027!$B$5:$B$22,0)),""),"") | U9: =IF($A9="","",IF(WEEKDAY($A9,2)>5,"Víkend",IF(COUNTIF(SVATKY_2027!$B$5:$B$22,$A9)>0,"Svátek",""))) | V9: =IF(OR($A9="",$U9="Víkend"),0,IF($U9="Svátek",1,MIN(1,COUNTIF($K9:$P9,"x")+COUNTIF($K9:$P9,1)+0.5*COUNTIF($K9:$P9,0.5)+IF(OR($R9="x",$R9=1),1,IF($R9=0.5,0.5,0))))) -> 0
A10: =IF(MONTH(DATE(PREDVOLBY!$C$8,1,5))=1,DATE(PREDVOLBY!$C$8,1,5),"") -> 46392 | B10: =IF($A10="","",CHOOSE(WEEKDAY($A10,2),"po","út","st","čt","pá","so","ne")) -> út | C10: =IF(OR($A10="",$U10="Víkend"),"",IF($V10>=1,"-",PREDVOLBY!$C$18)) -> 0.3125 | D10: =IF(OR($A10="",$U10="Víkend"),"",IF($V10>=1,"-",PREDVOLBY!$C$19)) -> 0.47916667 | E10: =IF(OR($A10="",$U10="Víkend"),"",IF($V10>=0.5,"-",PREDVOLBY!$C$20)) -> 0.5 | F10: =IF(OR($A10="",$U10="Víkend"),"",IF($V10>=0.5,"-",PREDVOLBY!$C$21)) -> 0.66666667 | G10: =IF(OR($A10="",$U10="Víkend"),"",IF(ISNUMBER($C10)+ISNUMBER($E10)=0,"-",ROUND((IF(ISNUMBER($C10),$D10-$C10,0)+IF(ISNUMBER($E10),$F10-$E10,0))*24,2))) -> 8 | H10: =IF($G10="","",IF(ISNUMBER($G10),MAX(0,ROUND($G10-PREDVOLBY!$C$22*(1-$V10),2)),"-")) -> 0 | I10: =IF($G10="","",IF(AND(ISNUMBER($G10),$J10=""),IF($G10>=PREDVOLBY!$C$26,PREDVOLBY!$C$25,"-"),"-")) -> 129.5 | M10: =IF($U10="Svátek",1,"") | S10: =IF($U10="Svátek",IFERROR(INDEX(SVATKY_2027!$C$5:$C$22,MATCH($A10,SVATKY_2027!$B$5:$B$22,0)),""),"") | U10: =IF($A10="","",IF(WEEKDAY($A10,2)>5,"Víkend",IF(COUNTIF(SVATKY_2027!$B$5:$B$22,$A10)>0,"Svátek",""))) | V10: =IF(OR($A10="",$U10="Víkend"),0,IF($U10="Svátek",1,MIN(1,COUNTIF($K10:$P10,"x")+COUNTIF($K10:$P10,1)+0.5*COUNTIF($K10:$P10,0.5)+IF(OR($R10="x",$R10=1),1,IF($R10=0.5,0.5,0))))) -> 0
A11: =IF(MONTH(DATE(PREDVOLBY!$C$8,1,6))=1,DATE(PREDVOLBY!$C$8,1,6),"") -> 46393 | B11: =IF($A11="","",CHOOSE(WEEKDAY($A11,2),"po","út","st","čt","pá","so","ne")) -> st | C11: =IF(OR($A11="",$U11="Víkend"),"",IF($V11>=1,"-",PREDVOLBY!$C$18)) -> 0.3125 | D11: =IF(OR($A11="",$U11="Víkend"),"",IF($V11>=1,"-",PREDVOLBY!$C$19)) -> 0.47916667 | E11: =IF(OR($A11="",$U11="Víkend"),"",IF($V11>=0.5,"-",PREDVOLBY!$C$20)) -> 0.5 | F11: =IF(OR($A11="",$U11="Víkend"),"",IF($V11>=0.5,"-",PREDVOLBY!$C$21)) -> 0.66666667 | G11: =IF(OR($A11="",$U11="Víkend"),"",IF(ISNUMBER($C11)+ISNUMBER($E11)=0,"-",ROUND((IF(ISNUMBER($C11),$D11-$C11,0)+IF(ISNUMBER($E11),$F11-$E11,0))*24,2))) -> 8 | H11: =IF($G11="","",IF(ISNUMBER($G11),MAX(0,ROUND($G11-PREDVOLBY!$C$22*(1-$V11),2)),"-")) -> 0 | I11: =IF($G11="","",IF(AND(ISNUMBER($G11),$J11=""),IF($G11>=PREDVOLBY!$C$26,PREDVOLBY!$C$25,"-"),"-")) -> 129.5 | M11: =IF($U11="Svátek",1,"") | S11: =IF($U11="Svátek",IFERROR(INDEX(SVATKY_2027!$C$5:$C$22,MATCH($A11,SVATKY_2027!$B$5:$B$22,0)),""),"") | U11: =IF($A11="","",IF(WEEKDAY($A11,2)>5,"Víkend",IF(COUNTIF(SVATKY_2027!$B$5:$B$22,$A11)>0,"Svátek",""))) | V11: =IF(OR($A11="",$U11="Víkend"),0,IF($U11="Svátek",1,MIN(1,COUNTIF($K11:$P11,"x")+COUNTIF($K11:$P11,1)+0.5*COUNTIF($K11:$P11,0.5)+IF(OR($R11="x",$R11=1),1,IF($R11=0.5,0.5,0))))) -> 0
A12: =IF(MONTH(DATE(PREDVOLBY!$C$8,1,7))=1,DATE(PREDVOLBY!$C$8,1,7),"") -> 46394 | B12: =IF($A12="","",CHOOSE(WEEKDAY($A12,2),"po","út","st","čt","pá","so","ne")) -> čt | C12: =IF(OR($A12="",$U12="Víkend"),"",IF($V12>=1,"-",PREDVOLBY!$C$18)) -> 0.3125 | D12: =IF(OR($A12="",$U12="Víkend"),"",IF($V12>=1,"-",PREDVOLBY!$C$19)) -> 0.47916667 | E12: =IF(OR($A12="",$U12="Víkend"),"",IF($V12>=0.5,"-",PREDVOLBY!$C$20)) -> 0.5 | F12: =IF(OR($A12="",$U12="Víkend"),"",IF($V12>=0.5,"-",PREDVOLBY!$C$21)) -> 0.66666667 | G12: =IF(OR($A12="",$U12="Víkend"),"",IF(ISNUMBER($C12)+ISNUMBER($E12)=0,"-",ROUND((IF(ISNUMBER($C12),$D12-$C12,0)+IF(ISNUMBER($E12),$F12-$E12,0))*24,2))) -> 8 | H12: =IF($G12="","",IF(ISNUMBER($G12),MAX(0,ROUND($G12-PREDVOLBY!$C$22*(1-$V12),2)),"-")) -> 0 | I12: =IF($G12="","",IF(AND(ISNUMBER($G12),$J12=""),IF($G12>=PREDVOLBY!$C$26,PREDVOLBY!$C$25,"-"),"-")) -> 129.5 | M12: =IF($U12="Svátek",1,"") | S12: =IF($U12="Svátek",IFERROR(INDEX(SVATKY_2027!$C$5:$C$22,MATCH($A12,SVATKY_2027!$B$5:$B$22,0)),""),"") | U12: =IF($A12="","",IF(WEEKDAY($A12,2)>5,"Víkend",IF(COUNTIF(SVATKY_2027!$B$5:$B$22,$A12)>0,"Svátek",""))) | V12: =IF(OR($A12="",$U12="Víkend"),0,IF($U12="Svátek",1,MIN(1,COUNTIF($K12:$P12,"x")+COUNTIF($K12:$P12,1)+0.5*COUNTIF($K12:$P12,0.5)+IF(OR($R12="x",$R12=1),1,IF($R12=0.5,0.5,0))))) -> 0
A13: =IF(MONTH(DATE(PREDVOLBY!$C$8,1,8))=1,DATE(PREDVOLBY!$C$8,1,8),"") -> 46395 | B13: =IF($A13="","",CHOOSE(WEEKDAY($A13,2),"po","út","st","čt","pá","so","ne")) -> pá | C13: =IF(OR($A13="",$U13="Víkend"),"",IF($V13>=1,"-",PREDVOLBY!$C$18)) -> 0.3125 | D13: =IF(OR($A13="",$U13="Víkend"),"",IF($V13>=1,"-",PREDVOLBY!$C$19)) -> 0.47916667 | E13: =IF(OR($A13="",$U13="Víkend"),"",IF($V13>=0.5,"-",PREDVOLBY!$C$20)) -> 0.5 | F13: =IF(OR($A13="",$U13="Víkend"),"",IF($V13>=0.5,"-",PREDVOLBY!$C$21)) -> 0.66666667 | G13: =IF(OR($A13="",$U13="Víkend"),"",IF(ISNUMBER($C13)+ISNUMBER($E13)=0,"-",ROUND((IF(ISNUMBER($C13),$D13-$C13,0)+IF(ISNUMBER($E13),$F13-$E13,0))*24,2))) -> 8 | H13: =IF($G13="","",IF(ISNUMBER($G13),MAX(0,ROUND($G13-PREDVOLBY!$C$22*(1-$V13),2)),"-")) -> 0 | I13: =IF($G13="","",IF(AND(ISNUMBER($G13),$J13=""),IF($G13>=PREDVOLBY!$C$26,PREDVOLBY!$C$25,"-"),"-")) -> 129.5 | M13: =IF($U13="Svátek",1,"") | S13: =IF($U13="Svátek",IFERROR(INDEX(SVATKY_2027!$C$5:$C$22,MATCH($A13,SVATKY_2027!$B$5:$B$22,0)),""),"") | U13: =IF($A13="","",IF(WEEKDAY($A13,2)>5,"Víkend",IF(COUNTIF(SVATKY_2027!$B$5:$B$22,$A13)>0,"Svátek",""))) | V13: =IF(OR($A13="",$U13="Víkend"),0,IF($U13="Svátek",1,MIN(1,COUNTIF($K13:$P13,"x")+COUNTIF($K13:$P13,1)+0.5*COUNTIF($K13:$P13,0.5)+IF(OR($R13="x",$R13=1),1,IF($R13=0.5,0.5,0))))) -> 0
A14: =IF(MONTH(DATE(PREDVOLBY!$C$8,1,9))=1,DATE(PREDVOLBY!$C$8,1,9),"") -> 46396 | B14: =IF($A14="","",CHOOSE(WEEKDAY($A14,2),"po","út","st","čt","pá","so","ne")) -> so | C14: =IF(OR($A14="",$U14="Víkend"),"",IF($V14>=1,"-",PREDVOLBY!$C$18)) | D14: =IF(OR($A14="",$U14="Víkend"),"",IF($V14>=1,"-",PREDVOLBY!$C$19)) | E14: =IF(OR($A14="",$U14="Víkend"),"",IF($V14>=0.5,"-",PREDVOLBY!$C$20)) | F14: =IF(OR($A14="",$U14="Víkend"),"",IF($V14>=0.5,"-",PREDVOLBY!$C$21)) | G14: =IF(OR($A14="",$U14="Víkend"),"",IF(ISNUMBER($C14)+ISNUMBER($E14)=0,"-",ROUND((IF(ISNUMBER($C14),$D14-$C14,0)+IF(ISNUMBER($E14),$F14-$E14,0))*24,2))) | H14: =IF($G14="","",IF(ISNUMBER($G14),MAX(0,ROUND($G14-PREDVOLBY!$C$22*(1-$V14),2)),"-")) | I14: =IF($G14="","",IF(AND(ISNUMBER($G14),$J14=""),IF($G14>=PREDVOLBY!$C$26,PREDVOLBY!$C$25,"-"),"-")) | M14: =IF($U14="Svátek",1,"") | S14: =IF($U14="Svátek",IFERROR(INDEX(SVATKY_2027!$C$5:$C$22,MATCH($A14,SVATKY_2027!$B$5:$B$22,0)),""),"") | U14: =IF($A14="","",IF(WEEKDAY($A14,2)>5,"Víkend",IF(COUNTIF(SVATKY_2027!$B$5:$B$22,$A14)>0,"Svátek",""))) -> Víkend | V14: =IF(OR($A14="",$U14="Víkend"),0,IF($U14="Svátek",1,MIN(1,COUNTIF($K14:$P14,"x")+COUNTIF($K14:$P14,1)+0.5*COUNTIF($K14:$P14,0.5)+IF(OR($R14="x",$R14=1),1,IF($R14=0.5,0.5,0))))) -> 0
A15: =IF(MONTH(DATE(PREDVOLBY!$C$8,1,10))=1,DATE(PREDVOLBY!$C$8,1,10),"") -> 46397 | B15: =IF($A15="","",CHOOSE(WEEKDAY($A15,2),"po","út","st","čt","pá","so","ne")) -> ne | C15: =IF(OR($A15="",$U15="Víkend"),"",IF($V15>=1,"-",PREDVOLBY!$C$18)) | D15: =IF(OR($A15="",$U15="Víkend"),"",IF($V15>=1,"-",PREDVOLBY!$C$19)) | E15: =IF(OR($A15="",$U15="Víkend"),"",IF($V15>=0.5,"-",PREDVOLBY!$C$20)) | F15: =IF(OR($A15="",$U15="Víkend"),"",IF($V15>=0.5,"-",PREDVOLBY!$C$21)) | G15: =IF(OR($A15="",$U15="Víkend"),"",IF(ISNUMBER($C15)+ISNUMBER($E15)=0,"-",ROUND((IF(ISNUMBER($C15),$D15-$C15,0)+IF(ISNUMBER($E15),$F15-$E15,0))*24,2))) | H15: =IF($G15="","",IF(ISNUMBER($G15),MAX(0,ROUND($G15-PREDVOLBY!$C$22*(1-$V15),2)),"-")) | I15: =IF($G15="","",IF(AND(ISNUMBER($G15),$J15=""),IF($G15>=PREDVOLBY!$C$26,PREDVOLBY!$C$25,"-"),"-")) | M15: =IF($U15="Svátek",1,"") | S15: =IF($U15="Svátek",IFERROR(INDEX(SVATKY_2027!$C$5:$C$22,MATCH($A15,SVATKY_2027!$B$5:$B$22,0)),""),"") | U15: =IF($A15="","",IF(WEEKDAY($A15,2)>5,"Víkend",IF(COUNTIF(SVATKY_2027!$B$5:$B$22,$A15)>0,"Svátek",""))) -> Víkend | V15: =IF(OR($A15="",$U15="Víkend"),0,IF($U15="Svátek",1,MIN(1,COUNTIF($K15:$P15,"x")+COUNTIF($K15:$P15,1)+0.5*COUNTIF($K15:$P15,0.5)+IF(OR($R15="x",$R15=1),1,IF($R15=0.5,0.5,0))))) -> 0
A16: =IF(MONTH(DATE(PREDVOLBY!$C$8,1,11))=1,DATE(PREDVOLBY!$C$8,1,11),"") -> 46398 | B16: =IF($A16="","",CHOOSE(WEEKDAY($A16,2),"po","út","st","čt","pá","so","ne")) -> po | C16: =IF(OR($A16="",$U16="Víkend"),"",IF($V16>=1,"-",PREDVOLBY!$C$18)) -> 0.3125 | D16: =IF(OR($A16="",$U16="Víkend"),"",IF($V16>=1,"-",PREDVOLBY!$C$19)) -> 0.47916667 | E16: =IF(OR($A16="",$U16="Víkend"),"",IF($V16>=0.5,"-",PREDVOLBY!$C$20)) -> 0.5 | F16: =IF(OR($A16="",$U16="Víkend"),"",IF($V16>=0.5,"-",PREDVOLBY!$C$21)) -> 0.66666667 | G16: =IF(OR($A16="",$U16="Víkend"),"",IF(ISNUMBER($C16)+ISNUMBER($E16)=0,"-",ROUND((IF(ISNUMBER($C16),$D16-$C16,0)+IF(ISNUMBER($E16),$F16-$E16,0))*24,2))) -> 8 | H16: =IF($G16="","",IF(ISNUMBER($G16),MAX(0,ROUND($G16-PREDVOLBY!$C$22*(1-$V16),2)),"-")) -> 0 | I16: =IF($G16="","",IF(AND(ISNUMBER($G16),$J16=""),IF($G16>=PREDVOLBY!$C$26,PREDVOLBY!$C$25,"-"),"-")) -> 129.5 | M16: =IF($U16="Svátek",1,"") | S16: =IF($U16="Svátek",IFERROR(INDEX(SVATKY_2027!$C$5:$C$22,MATCH($A16,SVATKY_2027!$B$5:$B$22,0)),""),"") | U16: =IF($A16="","",IF(WEEKDAY($A16,2)>5,"Víkend",IF(COUNTIF(SVATKY_2027!$B$5:$B$22,$A16)>0,"Svátek",""))) | V16: =IF(OR($A16="",$U16="Víkend"),0,IF($U16="Svátek",1,MIN(1,COUNTIF($K16:$P16,"x")+COUNTIF($K16:$P16,1)+0.5*COUNTIF($K16:$P16,0.5)+IF(OR($R16="x",$R16=1),1,IF($R16=0.5,0.5,0))))) -> 0
A17: =IF(MONTH(DATE(PREDVOLBY!$C$8,1,12))=1,DATE(PREDVOLBY!$C$8,1,12),"") -> 46399 | B17: =IF($A17="","",CHOOSE(WEEKDAY($A17,2),"po","út","st","čt","pá","so","ne")) -> út | C17: =IF(OR($A17="",$U17="Víkend"),"",IF($V17>=1,"-",PREDVOLBY!$C$18)) -> 0.3125 | D17: =IF(OR($A17="",$U17="Víkend"),"",IF($V17>=1,"-",PREDVOLBY!$C$19)) -> 0.47916667 | E17: =IF(OR($A17="",$U17="Víkend"),"",IF($V17>=0.5,"-",PREDVOLBY!$C$20)) -> 0.5 | F17: =IF(OR($A17="",$U17="Víkend"),"",IF($V17>=0.5,"-",PREDVOLBY!$C$21)) -> 0.66666667 | G17: =IF(OR($A17="",$U17="Víkend"),"",IF(ISNUMBER($C17)+ISNUMBER($E17)=0,"-",ROUND((IF(ISNUMBER($C17),$D17-$C17,0)+IF(ISNUMBER($E17),$F17-$E17,0))*24,2))) -> 8 | H17: =IF($G17="","",IF(ISNUMBER($G17),MAX(0,ROUND($G17-PREDVOLBY!$C$22*(1-$V17),2)),"-")) -> 0 | I17: =IF($G17="","",IF(AND(ISNUMBER($G17),$J17=""),IF($G17>=PREDVOLBY!$C$26,PREDVOLBY!$C$25,"-"),"-")) -> 129.5 | M17: =IF($U17="Svátek",1,"") | S17: =IF($U17="Svátek",IFERROR(INDEX(SVATKY_2027!$C$5:$C$22,MATCH($A17,SVATKY_2027!$B$5:$B$22,0)),""),"") | U17: =IF($A17="","",IF(WEEKDAY($A17,2)>5,"Víkend",IF(COUNTIF(SVATKY_2027!$B$5:$B$22,$A17)>0,"Svátek",""))) | V17: =IF(OR($A17="",$U17="Víkend"),0,IF($U17="Svátek",1,MIN(1,COUNTIF($K17:$P17,"x")+COUNTIF($K17:$P17,1)+0.5*COUNTIF($K17:$P17,0.5)+IF(OR($R17="x",$R17=1),1,IF($R17=0.5,0.5,0))))) -> 0
A18: =IF(MONTH(DATE(PREDVOLBY!$C$8,1,13))=1,DATE(PREDVOLBY!$C$8,1,13),"") -> 46400 | B18: =IF($A18="","",CHOOSE(WEEKDAY($A18,2),"po","út","st","čt","pá","so","ne")) -> st | C18: =IF(OR($A18="",$U18="Víkend"),"",IF($V18>=1,"-",PREDVOLBY!$C$18)) -> 0.3125 | D18: =IF(OR($A18="",$U18="Víkend"),"",IF($V18>=1,"-",PREDVOLBY!$C$19)) -> 0.47916667 | E18: =IF(OR($A18="",$U18="Víkend"),"",IF($V18>=0.5,"-",PREDVOLBY!$C$20)) -> 0.5 | F18: =IF(OR($A18="",$U18="Víkend"),"",IF($V18>=0.5,"-",PREDVOLBY!$C$21)) -> 0.66666667 | G18: =IF(OR($A18="",$U18="Víkend"),"",IF(ISNUMBER($C18)+ISNUMBER($E18)=0,"-",ROUND((IF(ISNUMBER($C18),$D18-$C18,0)+IF(ISNUMBER($E18),$F18-$E18,0))*24,2))) -> 8 | H18: =IF($G18="","",IF(ISNUMBER($G18),MAX(0,ROUND($G18-PREDVOLBY!$C$22*(1-$V18),2)),"-")) -> 0 | I18: =IF($G18="","",IF(AND(ISNUMBER($G18),$J18=""),IF($G18>=PREDVOLBY!$C$26,PREDVOLBY!$C$25,"-"),"-")) -> 129.5 | M18: =IF($U18="Svátek",1,"") | S18: =IF($U18="Svátek",IFERROR(INDEX(SVATKY_2027!$C$5:$C$22,MATCH($A18,SVATKY_2027!$B$5:$B$22,0)),""),"") | U18: =IF($A18="","",IF(WEEKDAY($A18,2)>5,"Víkend",IF(COUNTIF(SVATKY_2027!$B$5:$B$22,$A18)>0,"Svátek",""))) | V18: =IF(OR($A18="",$U18="Víkend"),0,IF($U18="Svátek",1,MIN(1,COUNTIF($K18:$P18,"x")+COUNTIF($K18:$P18,1)+0.5*COUNTIF($K18:$P18,0.5)+IF(OR($R18="x",$R18=1),1,IF($R18=0.5,0.5,0))))) -> 0
A19: =IF(MONTH(DATE(PREDVOLBY!$C$8,1,14))=1,DATE(PREDVOLBY!$C$8,1,14),"") -> 46401 | B19: =IF($A19="","",CHOOSE(WEEKDAY($A19,2),"po","út","st","čt","pá","so","ne")) -> čt | C19: =IF(OR($A19="",$U19="Víkend"),"",IF($V19>=1,"-",PREDVOLBY!$C$18)) -> 0.3125 | D19: =IF(OR($A19="",$U19="Víkend"),"",IF($V19>=1,"-",PREDVOLBY!$C$19)) -> 0.47916667 | E19: =IF(OR($A19="",$U19="Víkend"),"",IF($V19>=0.5,"-",PREDVOLBY!$C$20)) -> 0.5 | F19: =IF(OR($A19="",$U19="Víkend"),"",IF($V19>=0.5,"-",PREDVOLBY!$C$21)) -> 0.66666667 | G19: =IF(OR($A19="",$U19="Víkend"),"",IF(ISNUMBER($C19)+ISNUMBER($E19)=0,"-",ROUND((IF(ISNUMBER($C19),$D19-$C19,0)+IF(ISNUMBER($E19),$F19-$E19,0))*24,2))) -> 8 | H19: =IF($G19="","",IF(ISNUMBER($G19),MAX(0,ROUND($G19-PREDVOLBY!$C$22*(1-$V19),2)),"-")) -> 0 | I19: =IF($G19="","",IF(AND(ISNUMBER($G19),$J19=""),IF($G19>=PREDVOLBY!$C$26,PREDVOLBY!$C$25,"-"),"-")) -> 129.5 | M19: =IF($U19="Svátek",1,"") | S19: =IF($U19="Svátek",IFERROR(INDEX(SVATKY_2027!$C$5:$C$22,MATCH($A19,SVATKY_2027!$B$5:$B$22,0)),""),"") | U19: =IF($A19="","",IF(WEEKDAY($A19,2)>5,"Víkend",IF(COUNTIF(SVATKY_2027!$B$5:$B$22,$A19)>0,"Svátek",""))) | V19: =IF(OR($A19="",$U19="Víkend"),0,IF($U19="Svátek",1,MIN(1,COUNTIF($K19:$P19,"x")+COUNTIF($K19:$P19,1)+0.5*COUNTIF($K19:$P19,0.5)+IF(OR($R19="x",$R19=1),1,IF($R19=0.5,0.5,0))))) -> 0
A20: =IF(MONTH(DATE(PREDVOLBY!$C$8,1,15))=1,DATE(PREDVOLBY!$C$8,1,15),"") -> 46402 | B20: =IF($A20="","",CHOOSE(WEEKDAY($A20,2),"po","út","st","čt","pá","so","ne")) -> pá | C20: =IF(OR($A20="",$U20="Víkend"),"",IF($V20>=1,"-",PREDVOLBY!$C$18)) -> 0.3125 | D20: =IF(OR($A20="",$U20="Víkend"),"",IF($V20>=1,"-",PREDVOLBY!$C$19)) -> 0.47916667 | E20: =IF(OR($A20="",$U20="Víkend"),"",IF($V20>=0.5,"-",PREDVOLBY!$C$20)) -> 0.5 | F20: =IF(OR($A20="",$U20="Víkend"),"",IF($V20>=0.5,"-",PREDVOLBY!$C$21)) -> 0.66666667 | G20: =IF(OR($A20="",$U20="Víkend"),"",IF(ISNUMBER($C20)+ISNUMBER($E20)=0,"-",ROUND((IF(ISNUMBER($C20),$D20-$C20,0)+IF(ISNUMBER($E20),$F20-$E20,0))*24,2))) -> 8 | H20: =IF($G20="","",IF(ISNUMBER($G20),MAX(0,ROUND($G20-PREDVOLBY!$C$22*(1-$V20),2)),"-")) -> 0 | I20: =IF($G20="","",IF(AND(ISNUMBER($G20),$J20=""),IF($G20>=PREDVOLBY!$C$26,PREDVOLBY!$C$25,"-"),"-")) -> 129.5 | M20: =IF($U20="Svátek",1,"") | S20: =IF($U20="Svátek",IFERROR(INDEX(SVATKY_2027!$C$5:$C$22,MATCH($A20,SVATKY_2027!$B$5:$B$22,0)),""),"") | U20: =IF($A20="","",IF(WEEKDAY($A20,2)>5,"Víkend",IF(COUNTIF(SVATKY_2027!$B$5:$B$22,$A20)>0,"Svátek",""))) | V20: =IF(OR($A20="",$U20="Víkend"),0,IF($U20="Svátek",1,MIN(1,COUNTIF($K20:$P20,"x")+COUNTIF($K20:$P20,1)+0.5*COUNTIF($K20:$P20,0.5)+IF(OR($R20="x",$R20=1),1,IF($R20=0.5,0.5,0))))) -> 0
A21: =IF(MONTH(DATE(PREDVOLBY!$C$8,1,16))=1,DATE(PREDVOLBY!$C$8,1,16),"") -> 46403 | B21: =IF($A21="","",CHOOSE(WEEKDAY($A21,2),"po","út","st","čt","pá","so","ne")) -> so | C21: =IF(OR($A21="",$U21="Víkend"),"",IF($V21>=1,"-",PREDVOLBY!$C$18)) | D21: =IF(OR($A21="",$U21="Víkend"),"",IF($V21>=1,"-",PREDVOLBY!$C$19)) | E21: =IF(OR($A21="",$U21="Víkend"),"",IF($V21>=0.5,"-",PREDVOLBY!$C$20)) | F21: =IF(OR($A21="",$U21="Víkend"),"",IF($V21>=0.5,"-",PREDVOLBY!$C$21)) | G21: =IF(OR($A21="",$U21="Víkend"),"",IF(ISNUMBER($C21)+ISNUMBER($E21)=0,"-",ROUND((IF(ISNUMBER($C21),$D21-$C21,0)+IF(ISNUMBER($E21),$F21-$E21,0))*24,2))) | H21: =IF($G21="","",IF(ISNUMBER($G21),MAX(0,ROUND($G21-PREDVOLBY!$C$22*(1-$V21),2)),"-")) | I21: =IF($G21="","",IF(AND(ISNUMBER($G21),$J21=""),IF($G21>=PREDVOLBY!$C$26,PREDVOLBY!$C$25,"-"),"-")) | M21: =IF($U21="Svátek",1,"") | S21: =IF($U21="Svátek",IFERROR(INDEX(SVATKY_2027!$C$5:$C$22,MATCH($A21,SVATKY_2027!$B$5:$B$22,0)),""),"") | U21: =IF($A21="","",IF(WEEKDAY($A21,2)>5,"Víkend",IF(COUNTIF(SVATKY_2027!$B$5:$B$22,$A21)>0,"Svátek",""))) -> Víkend | V21: =IF(OR($A21="",$U21="Víkend"),0,IF($U21="Svátek",1,MIN(1,COUNTIF($K21:$P21,"x")+COUNTIF($K21:$P21,1)+0.5*COUNTIF($K21:$P21,0.5)+IF(OR($R21="x",$R21=1),1,IF($R21=0.5,0.5,0))))) -> 0
A22: =IF(MONTH(DATE(PREDVOLBY!$C$8,1,17))=1,DATE(PREDVOLBY!$C$8,1,17),"") -> 46404 | B22: =IF($A22="","",CHOOSE(WEEKDAY($A22,2),"po","út","st","čt","pá","so","ne")) -> ne | C22: =IF(OR($A22="",$U22="Víkend"),"",IF($V22>=1,"-",PREDVOLBY!$C$18)) | D22: =IF(OR($A22="",$U22="Víkend"),"",IF($V22>=1,"-",PREDVOLBY!$C$19)) | E22: =IF(OR($A22="",$U22="Víkend"),"",IF($V22>=0.5,"-",PREDVOLBY!$C$20)) | F22: =IF(OR($A22="",$U22="Víkend"),"",IF($V22>=0.5,"-",PREDVOLBY!$C$21)) | G22: =IF(OR($A22="",$U22="Víkend"),"",IF(ISNUMBER($C22)+ISNUMBER($E22)=0,"-",ROUND((IF(ISNUMBER($C22),$D22-$C22,0)+IF(ISNUMBER($E22),$F22-$E22,0))*24,2))) | H22: =IF($G22="","",IF(ISNUMBER($G22),MAX(0,ROUND($G22-PREDVOLBY!$C$22*(1-$V22),2)),"-")) | I22: =IF($G22="","",IF(AND(ISNUMBER($G22),$J22=""),IF($G22>=PREDVOLBY!$C$26,PREDVOLBY!$C$25,"-"),"-")) | M22: =IF($U22="Svátek",1,"") | S22: =IF($U22="Svátek",IFERROR(INDEX(SVATKY_2027!$C$5:$C$22,MATCH($A22,SVATKY_2027!$B$5:$B$22,0)),""),"") | U22: =IF($A22="","",IF(WEEKDAY($A22,2)>5,"Víkend",IF(COUNTIF(SVATKY_2027!$B$5:$B$22,$A22)>0,"Svátek",""))) -> Víkend | V22: =IF(OR($A22="",$U22="Víkend"),0,IF($U22="Svátek",1,MIN(1,COUNTIF($K22:$P22,"x")+COUNTIF($K22:$P22,1)+0.5*COUNTIF($K22:$P22,0.5)+IF(OR($R22="x",$R22=1),1,IF($R22=0.5,0.5,0))))) -> 0
A23: =IF(MONTH(DATE(PREDVOLBY!$C$8,1,18))=1,DATE(PREDVOLBY!$C$8,1,18),"") -> 46405 | B23: =IF($A23="","",CHOOSE(WEEKDAY($A23,2),"po","út","st","čt","pá","so","ne")) -> po | C23: =IF(OR($A23="",$U23="Víkend"),"",IF($V23>=1,"-",PREDVOLBY!$C$18)) -> 0.3125 | D23: =IF(OR($A23="",$U23="Víkend"),"",IF($V23>=1,"-",PREDVOLBY!$C$19)) -> 0.47916667 | E23: =IF(OR($A23="",$U23="Víkend"),"",IF($V23>=0.5,"-",PREDVOLBY!$C$20)) -> 0.5 | F23: =IF(OR($A23="",$U23="Víkend"),"",IF($V23>=0.5,"-",PREDVOLBY!$C$21)) -> 0.66666667 | G23: =IF(OR($A23="",$U23="Víkend"),"",IF(ISNUMBER($C23)+ISNUMBER($E23)=0,"-",ROUND((IF(ISNUMBER($C23),$D23-$C23,0)+IF(ISNUMBER($E23),$F23-$E23,0))*24,2))) -> 8 | H23: =IF($G23="","",IF(ISNUMBER($G23),MAX(0,ROUND($G23-PREDVOLBY!$C$22*(1-$V23),2)),"-")) -> 0 | I23: =IF($G23="","",IF(AND(ISNUMBER($G23),$J23=""),IF($G23>=PREDVOLBY!$C$26,PREDVOLBY!$C$25,"-"),"-")) -> 129.5 | M23: =IF($U23="Svátek",1,"") | S23: =IF($U23="Svátek",IFERROR(INDEX(SVATKY_2027!$C$5:$C$22,MATCH($A23,SVATKY_2027!$B$5:$B$22,0)),""),"") | U23: =IF($A23="","",IF(WEEKDAY($A23,2)>5,"Víkend",IF(COUNTIF(SVATKY_2027!$B$5:$B$22,$A23)>0,"Svátek",""))) | V23: =IF(OR($A23="",$U23="Víkend"),0,IF($U23="Svátek",1,MIN(1,COUNTIF($K23:$P23,"x")+COUNTIF($K23:$P23,1)+0.5*COUNTIF($K23:$P23,0.5)+IF(OR($R23="x",$R23=1),1,IF($R23=0.5,0.5,0))))) -> 0
A24: =IF(MONTH(DATE(PREDVOLBY!$C$8,1,19))=1,DATE(PREDVOLBY!$C$8,1,19),"") -> 46406 | B24: =IF($A24="","",CHOOSE(WEEKDAY($A24,2),"po","út","st","čt","pá","so","ne")) -> út | C24: =IF(OR($A24="",$U24="Víkend"),"",IF($V24>=1,"-",PREDVOLBY!$C$18)) -> 0.3125 | D24: =IF(OR($A24="",$U24="Víkend"),"",IF($V24>=1,"-",PREDVOLBY!$C$19)) -> 0.47916667 | E24: =IF(OR($A24="",$U24="Víkend"),"",IF($V24>=0.5,"-",PREDVOLBY!$C$20)) -> 0.5 | F24: =IF(OR($A24="",$U24="Víkend"),"",IF($V24>=0.5,"-",PREDVOLBY!$C$21)) -> 0.66666667 | G24: =IF(OR($A24="",$U24="Víkend"),"",IF(ISNUMBER($C24)+ISNUMBER($E24)=0,"-",ROUND((IF(ISNUMBER($C24),$D24-$C24,0)+IF(ISNUMBER($E24),$F24-$E24,0))*24,2))) -> 8 | H24: =IF($G24="","",IF(ISNUMBER($G24),MAX(0,ROUND($G24-PREDVOLBY!$C$22*(1-$V24),2)),"-")) -> 0 | I24: =IF($G24="","",IF(AND(ISNUMBER($G24),$J24=""),IF($G24>=PREDVOLBY!$C$26,PREDVOLBY!$C$25,"-"),"-")) -> 129.5 | M24: =IF($U24="Svátek",1,"") | S24: =IF($U24="Svátek",IFERROR(INDEX(SVATKY_2027!$C$5:$C$22,MATCH($A24,SVATKY_2027!$B$5:$B$22,0)),""),"") | U24: =IF($A24="","",IF(WEEKDAY($A24,2)>5,"Víkend",IF(COUNTIF(SVATKY_2027!$B$5:$B$22,$A24)>0,"Svátek",""))) | V24: =IF(OR($A24="",$U24="Víkend"),0,IF($U24="Svátek",1,MIN(1,COUNTIF($K24:$P24,"x")+COUNTIF($K24:$P24,1)+0.5*COUNTIF($K24:$P24,0.5)+IF(OR($R24="x",$R24=1),1,IF($R24=0.5,0.5,0))))) -> 0
A25: =IF(MONTH(DATE(PREDVOLBY!$C$8,1,20))=1,DATE(PREDVOLBY!$C$8,1,20),"") -> 46407 | B25: =IF($A25="","",CHOOSE(WEEKDAY($A25,2),"po","út","st","čt","pá","so","ne")) -> st | C25: =IF(OR($A25="",$U25="Víkend"),"",IF($V25>=1,"-",PREDVOLBY!$C$18)) -> 0.3125 | D25: =IF(OR($A25="",$U25="Víkend"),"",IF($V25>=1,"-",PREDVOLBY!$C$19)) -> 0.47916667 | E25: =IF(OR($A25="",$U25="Víkend"),"",IF($V25>=0.5,"-",PREDVOLBY!$C$20)) -> 0.5 | F25: =IF(OR($A25="",$U25="Víkend"),"",IF($V25>=0.5,"-",PREDVOLBY!$C$21)) -> 0.66666667 | G25: =IF(OR($A25="",$U25="Víkend"),"",IF(ISNUMBER($C25)+ISNUMBER($E25)=0,"-",ROUND((IF(ISNUMBER($C25),$D25-$C25,0)+IF(ISNUMBER($E25),$F25-$E25,0))*24,2))) -> 8 | H25: =IF($G25="","",IF(ISNUMBER($G25),MAX(0,ROUND($G25-PREDVOLBY!$C$22*(1-$V25),2)),"-")) -> 0 | I25: =IF($G25="","",IF(AND(ISNUMBER($G25),$J25=""),IF($G25>=PREDVOLBY!$C$26,PREDVOLBY!$C$25,"-"),"-")) -> 129.5 | M25: =IF($U25="Svátek",1,"") | S25: =IF($U25="Svátek",IFERROR(INDEX(SVATKY_2027!$C$5:$C$22,MATCH($A25,SVATKY_2027!$B$5:$B$22,0)),""),"") | U25: =IF($A25="","",IF(WEEKDAY($A25,2)>5,"Víkend",IF(COUNTIF(SVATKY_2027!$B$5:$B$22,$A25)>0,"Svátek",""))) | V25: =IF(OR($A25="",$U25="Víkend"),0,IF($U25="Svátek",1,MIN(1,COUNTIF($K25:$P25,"x")+COUNTIF($K25:$P25,1)+0.5*COUNTIF($K25:$P25,0.5)+IF(OR($R25="x",$R25=1),1,IF($R25=0.5,0.5,0))))) -> 0
A26: =IF(MONTH(DATE(PREDVOLBY!$C$8,1,21))=1,DATE(PREDVOLBY!$C$8,1,21),"") -> 46408 | B26: =IF($A26="","",CHOOSE(WEEKDAY($A26,2),"po","út","st","čt","pá","so","ne")) -> čt | C26: =IF(OR($A26="",$U26="Víkend"),"",IF($V26>=1,"-",PREDVOLBY!$C$18)) -> 0.3125 | D26: =IF(OR($A26="",$U26="Víkend"),"",IF($V26>=1,"-",PREDVOLBY!$C$19)) -> 0.47916667 | E26: =IF(OR($A26="",$U26="Víkend"),"",IF($V26>=0.5,"-",PREDVOLBY!$C$20)) -> 0.5 | F26: =IF(OR($A26="",$U26="Víkend"),"",IF($V26>=0.5,"-",PREDVOLBY!$C$21)) -> 0.66666667 | G26: =IF(OR($A26="",$U26="Víkend"),"",IF(ISNUMBER($C26)+ISNUMBER($E26)=0,"-",ROUND((IF(ISNUMBER($C26),$D26-$C26,0)+IF(ISNUMBER($E26),$F26-$E26,0))*24,2))) -> 8 | H26: =IF($G26="","",IF(ISNUMBER($G26),MAX(0,ROUND($G26-PREDVOLBY!$C$22*(1-$V26),2)),"-")) -> 0 | I26: =IF($G26="","",IF(AND(ISNUMBER($G26),$J26=""),IF($G26>=PREDVOLBY!$C$26,PREDVOLBY!$C$25,"-"),"-")) -> 129.5 | M26: =IF($U26="Svátek",1,"") | S26: =IF($U26="Svátek",IFERROR(INDEX(SVATKY_2027!$C$5:$C$22,MATCH($A26,SVATKY_2027!$B$5:$B$22,0)),""),"") | U26: =IF($A26="","",IF(WEEKDAY($A26,2)>5,"Víkend",IF(COUNTIF(SVATKY_2027!$B$5:$B$22,$A26)>0,"Svátek",""))) | V26: =IF(OR($A26="",$U26="Víkend"),0,IF($U26="Svátek",1,MIN(1,COUNTIF($K26:$P26,"x")+COUNTIF($K26:$P26,1)+0.5*COUNTIF($K26:$P26,0.5)+IF(OR($R26="x",$R26=1),1,IF($R26=0.5,0.5,0))))) -> 0
A27: =IF(MONTH(DATE(PREDVOLBY!$C$8,1,22))=1,DATE(PREDVOLBY!$C$8,1,22),"") -> 46409 | B27: =IF($A27="","",CHOOSE(WEEKDAY($A27,2),"po","út","st","čt","pá","so","ne")) -> pá | C27: =IF(OR($A27="",$U27="Víkend"),"",IF($V27>=1,"-",PREDVOLBY!$C$18)) -> 0.3125 | D27: =IF(OR($A27="",$U27="Víkend"),"",IF($V27>=1,"-",PREDVOLBY!$C$19)) -> 0.47916667 | E27: =IF(OR($A27="",$U27="Víkend"),"",IF($V27>=0.5,"-",PREDVOLBY!$C$20)) -> 0.5 | F27: =IF(OR($A27="",$U27="Víkend"),"",IF($V27>=0.5,"-",PREDVOLBY!$C$21)) -> 0.66666667 | G27: =IF(OR($A27="",$U27="Víkend"),"",IF(ISNUMBER($C27)+ISNUMBER($E27)=0,"-",ROUND((IF(ISNUMBER($C27),$D27-$C27,0)+IF(ISNUMBER($E27),$F27-$E27,0))*24,2))) -> 8 | H27: =IF($G27="","",IF(ISNUMBER($G27),MAX(0,ROUND($G27-PREDVOLBY!$C$22*(1-$V27),2)),"-")) -> 0 | I27: =IF($G27="","",IF(AND(ISNUMBER($G27),$J27=""),IF($G27>=PREDVOLBY!$C$26,PREDVOLBY!$C$25,"-"),"-")) -> 129.5 | M27: =IF($U27="Svátek",1,"") | S27: =IF($U27="Svátek",IFERROR(INDEX(SVATKY_2027!$C$5:$C$22,MATCH($A27,SVATKY_2027!$B$5:$B$22,0)),""),"") | U27: =IF($A27="","",IF(WEEKDAY($A27,2)>5,"Víkend",IF(COUNTIF(SVATKY_2027!$B$5:$B$22,$A27)>0,"Svátek",""))) | V27: =IF(OR($A27="",$U27="Víkend"),0,IF($U27="Svátek",1,MIN(1,COUNTIF($K27:$P27,"x")+COUNTIF($K27:$P27,1)+0.5*COUNTIF($K27:$P27,0.5)+IF(OR($R27="x",$R27=1),1,IF($R27=0.5,0.5,0))))) -> 0
A28: =IF(MONTH(DATE(PREDVOLBY!$C$8,1,23))=1,DATE(PREDVOLBY!$C$8,1,23),"") -> 46410 | B28: =IF($A28="","",CHOOSE(WEEKDAY($A28,2),"po","út","st","čt","pá","so","ne")) -> so | C28: =IF(OR($A28="",$U28="Víkend"),"",IF($V28>=1,"-",PREDVOLBY!$C$18)) | D28: =IF(OR($A28="",$U28="Víkend"),"",IF($V28>=1,"-",PREDVOLBY!$C$19)) | E28: =IF(OR($A28="",$U28="Víkend"),"",IF($V28>=0.5,"-",PREDVOLBY!$C$20)) | F28: =IF(OR($A28="",$U28="Víkend"),"",IF($V28>=0.5,"-",PREDVOLBY!$C$21)) | G28: =IF(OR($A28="",$U28="Víkend"),"",IF(ISNUMBER($C28)+ISNUMBER($E28)=0,"-",ROUND((IF(ISNUMBER($C28),$D28-$C28,0)+IF(ISNUMBER($E28),$F28-$E28,0))*24,2))) | H28: =IF($G28="","",IF(ISNUMBER($G28),MAX(0,ROUND($G28-PREDVOLBY!$C$22*(1-$V28),2)),"-")) | I28: =IF($G28="","",IF(AND(ISNUMBER($G28),$J28=""),IF($G28>=PREDVOLBY!$C$26,PREDVOLBY!$C$25,"-"),"-")) | M28: =IF($U28="Svátek",1,"") | S28: =IF($U28="Svátek",IFERROR(INDEX(SVATKY_2027!$C$5:$C$22,MATCH($A28,SVATKY_2027!$B$5:$B$22,0)),""),"") | U28: =IF($A28="","",IF(WEEKDAY($A28,2)>5,"Víkend",IF(COUNTIF(SVATKY_2027!$B$5:$B$22,$A28)>0,"Svátek",""))) -> Víkend | V28: =IF(OR($A28="",$U28="Víkend"),0,IF($U28="Svátek",1,MIN(1,COUNTIF($K28:$P28,"x")+COUNTIF($K28:$P28,1)+0.5*COUNTIF($K28:$P28,0.5)+IF(OR($R28="x",$R28=1),1,IF($R28=0.5,0.5,0))))) -> 0
A29: =IF(MONTH(DATE(PREDVOLBY!$C$8,1,24))=1,DATE(PREDVOLBY!$C$8,1,24),"") -> 46411 | B29: =IF($A29="","",CHOOSE(WEEKDAY($A29,2),"po","út","st","čt","pá","so","ne")) -> ne | C29: =IF(OR($A29="",$U29="Víkend"),"",IF($V29>=1,"-",PREDVOLBY!$C$18)) | D29: =IF(OR($A29="",$U29="Víkend"),"",IF($V29>=1,"-",PREDVOLBY!$C$19)) | E29: =IF(OR($A29="",$U29="Víkend"),"",IF($V29>=0.5,"-",PREDVOLBY!$C$20)) | F29: =IF(OR($A29="",$U29="Víkend"),"",IF($V29>=0.5,"-",PREDVOLBY!$C$21)) | G29: =IF(OR($A29="",$U29="Víkend"),"",IF(ISNUMBER($C29)+ISNUMBER($E29)=0,"-",ROUND((IF(ISNUMBER($C29),$D29-$C29,0)+IF(ISNUMBER($E29),$F29-$E29,0))*24,2))) | H29: =IF($G29="","",IF(ISNUMBER($G29),MAX(0,ROUND($G29-PREDVOLBY!$C$22*(1-$V29),2)),"-")) | I29: =IF($G29="","",IF(AND(ISNUMBER($G29),$J29=""),IF($G29>=PREDVOLBY!$C$26,PREDVOLBY!$C$25,"-"),"-")) | M29: =IF($U29="Svátek",1,"") | S29: =IF($U29="Svátek",IFERROR(INDEX(SVATKY_2027!$C$5:$C$22,MATCH($A29,SVATKY_2027!$B$5:$B$22,0)),""),"") | U29: =IF($A29="","",IF(WEEKDAY($A29,2)>5,"Víkend",IF(COUNTIF(SVATKY_2027!$B$5:$B$22,$A29)>0,"Svátek",""))) -> Víkend | V29: =IF(OR($A29="",$U29="Víkend"),0,IF($U29="Svátek",1,MIN(1,COUNTIF($K29:$P29,"x")+COUNTIF($K29:$P29,1)+0.5*COUNTIF($K29:$P29,0.5)+IF(OR($R29="x",$R29=1),1,IF($R29=0.5,0.5,0))))) -> 0
A30: =IF(MONTH(DATE(PREDVOLBY!$C$8,1,25))=1,DATE(PREDVOLBY!$C$8,1,25),"") -> 46412 | B30: =IF($A30="","",CHOOSE(WEEKDAY($A30,2),"po","út","st","čt","pá","so","ne")) -> po | C30: =IF(OR($A30="",$U30="Víkend"),"",IF($V30>=1,"-",PREDVOLBY!$C$18)) -> 0.3125 | D30: =IF(OR($A30="",$U30="Víkend"),"",IF($V30>=1,"-",PREDVOLBY!$C$19)) -> 0.47916667 | E30: =IF(OR($A30="",$U30="Víkend"),"",IF($V30>=0.5,"-",PREDVOLBY!$C$20)) -> 0.5 | F30: =IF(OR($A30="",$U30="Víkend"),"",IF($V30>=0.5,"-",PREDVOLBY!$C$21)) -> 0.66666667 | G30: =IF(OR($A30="",$U30="Víkend"),"",IF(ISNUMBER($C30)+ISNUMBER($E30)=0,"-",ROUND((IF(ISNUMBER($C30),$D30-$C30,0)+IF(ISNUMBER($E30),$F30-$E30,0))*24,2))) -> 8 | H30: =IF($G30="","",IF(ISNUMBER($G30),MAX(0,ROUND($G30-PREDVOLBY!$C$22*(1-$V30),2)),"-")) -> 0 | I30: =IF($G30="","",IF(AND(ISNUMBER($G30),$J30=""),IF($G30>=PREDVOLBY!$C$26,PREDVOLBY!$C$25,"-"),"-")) -> 129.5 | M30: =IF($U30="Svátek",1,"") | S30: =IF($U30="Svátek",IFERROR(INDEX(SVATKY_2027!$C$5:$C$22,MATCH($A30,SVATKY_2027!$B$5:$B$22,0)),""),"") | U30: =IF($A30="","",IF(WEEKDAY($A30,2)>5,"Víkend",IF(COUNTIF(SVATKY_2027!$B$5:$B$22,$A30)>0,"Svátek",""))) | V30: =IF(OR($A30="",$U30="Víkend"),0,IF($U30="Svátek",1,MIN(1,COUNTIF($K30:$P30,"x")+COUNTIF($K30:$P30,1)+0.5*COUNTIF($K30:$P30,0.5)+IF(OR($R30="x",$R30=1),1,IF($R30=0.5,0.5,0))))) -> 0
A31: =IF(MONTH(DATE(PREDVOLBY!$C$8,1,26))=1,DATE(PREDVOLBY!$C$8,1,26),"") -> 46413 | B31: =IF($A31="","",CHOOSE(WEEKDAY($A31,2),"po","út","st","čt","pá","so","ne")) -> út | C31: =IF(OR($A31="",$U31="Víkend"),"",IF($V31>=1,"-",PREDVOLBY!$C$18)) -> 0.3125 | D31: =IF(OR($A31="",$U31="Víkend"),"",IF($V31>=1,"-",PREDVOLBY!$C$19)) -> 0.47916667 | E31: =IF(OR($A31="",$U31="Víkend"),"",IF($V31>=0.5,"-",PREDVOLBY!$C$20)) -> 0.5 | F31: =IF(OR($A31="",$U31="Víkend"),"",IF($V31>=0.5,"-",PREDVOLBY!$C$21)) -> 0.66666667 | G31: =IF(OR($A31="",$U31="Víkend"),"",IF(ISNUMBER($C31)+ISNUMBER($E31)=0,"-",ROUND((IF(ISNUMBER($C31),$D31-$C31,0)+IF(ISNUMBER($E31),$F31-$E31,0))*24,2))) -> 8 | H31: =IF($G31="","",IF(ISNUMBER($G31),MAX(0,ROUND($G31-PREDVOLBY!$C$22*(1-$V31),2)),"-")) -> 0 | I31: =IF($G31="","",IF(AND(ISNUMBER($G31),$J31=""),IF($G31>=PREDVOLBY!$C$26,PREDVOLBY!$C$25,"-"),"-")) -> 129.5 | M31: =IF($U31="Svátek",1,"") | S31: =IF($U31="Svátek",IFERROR(INDEX(SVATKY_2027!$C$5:$C$22,MATCH($A31,SVATKY_2027!$B$5:$B$22,0)),""),"") | U31: =IF($A31="","",IF(WEEKDAY($A31,2)>5,"Víkend",IF(COUNTIF(SVATKY_2027!$B$5:$B$22,$A31)>0,"Svátek",""))) | V31: =IF(OR($A31="",$U31="Víkend"),0,IF($U31="Svátek",1,MIN(1,COUNTIF($K31:$P31,"x")+COUNTIF($K31:$P31,1)+0.5*COUNTIF($K31:$P31,0.5)+IF(OR($R31="x",$R31=1),1,IF($R31=0.5,0.5,0))))) -> 0
A32: =IF(MONTH(DATE(PREDVOLBY!$C$8,1,27))=1,DATE(PREDVOLBY!$C$8,1,27),"") -> 46414 | B32: =IF($A32="","",CHOOSE(WEEKDAY($A32,2),"po","út","st","čt","pá","so","ne")) -> st | C32: =IF(OR($A32="",$U32="Víkend"),"",IF($V32>=1,"-",PREDVOLBY!$C$18)) -> 0.3125 | D32: =IF(OR($A32="",$U32="Víkend"),"",IF($V32>=1,"-",PREDVOLBY!$C$19)) -> 0.47916667 | E32: =IF(OR($A32="",$U32="Víkend"),"",IF($V32>=0.5,"-",PREDVOLBY!$C$20)) -> 0.5 | F32: =IF(OR($A32="",$U32="Víkend"),"",IF($V32>=0.5,"-",PREDVOLBY!$C$21)) -> 0.66666667 | G32: =IF(OR($A32="",$U32="Víkend"),"",IF(ISNUMBER($C32)+ISNUMBER($E32)=0,"-",ROUND((IF(ISNUMBER($C32),$D32-$C32,0)+IF(ISNUMBER($E32),$F32-$E32,0))*24,2))) -> 8 | H32: =IF($G32="","",IF(ISNUMBER($G32),MAX(0,ROUND($G32-PREDVOLBY!$C$22*(1-$V32),2)),"-")) -> 0 | I32: =IF($G32="","",IF(AND(ISNUMBER($G32),$J32=""),IF($G32>=PREDVOLBY!$C$26,PREDVOLBY!$C$25,"-"),"-")) -> 129.5 | M32: =IF($U32="Svátek",1,"") | S32: =IF($U32="Svátek",IFERROR(INDEX(SVATKY_2027!$C$5:$C$22,MATCH($A32,SVATKY_2027!$B$5:$B$22,0)),""),"") | U32: =IF($A32="","",IF(WEEKDAY($A32,2)>5,"Víkend",IF(COUNTIF(SVATKY_2027!$B$5:$B$22,$A32)>0,"Svátek",""))) | V32: =IF(OR($A32="",$U32="Víkend"),0,IF($U32="Svátek",1,MIN(1,COUNTIF($K32:$P32,"x")+COUNTIF($K32:$P32,1)+0.5*COUNTIF($K32:$P32,0.5)+IF(OR($R32="x",$R32=1),1,IF($R32=0.5,0.5,0))))) -> 0
A33: =IF(MONTH(DATE(PREDVOLBY!$C$8,1,28))=1,DATE(PREDVOLBY!$C$8,1,28),"") -> 46415 | B33: =IF($A33="","",CHOOSE(WEEKDAY($A33,2),"po","út","st","čt","pá","so","ne")) -> čt | C33: =IF(OR($A33="",$U33="Víkend"),"",IF($V33>=1,"-",PREDVOLBY!$C$18)) -> 0.3125 | D33: =IF(OR($A33="",$U33="Víkend"),"",IF($V33>=1,"-",PREDVOLBY!$C$19)) -> 0.47916667 | E33: =IF(OR($A33="",$U33="Víkend"),"",IF($V33>=0.5,"-",PREDVOLBY!$C$20)) -> 0.5 | F33: =IF(OR($A33="",$U33="Víkend"),"",IF($V33>=0.5,"-",PREDVOLBY!$C$21)) -> 0.66666667 | G33: =IF(OR($A33="",$U33="Víkend"),"",IF(ISNUMBER($C33)+ISNUMBER($E33)=0,"-",ROUND((IF(ISNUMBER($C33),$D33-$C33,0)+IF(ISNUMBER($E33),$F33-$E33,0))*24,2))) -> 8 | H33: =IF($G33="","",IF(ISNUMBER($G33),MAX(0,ROUND($G33-PREDVOLBY!$C$22*(1-$V33),2)),"-")) -> 0 | I33: =IF($G33="","",IF(AND(ISNUMBER($G33),$J33=""),IF($G33>=PREDVOLBY!$C$26,PREDVOLBY!$C$25,"-"),"-")) -> 129.5 | M33: =IF($U33="Svátek",1,"") | S33: =IF($U33="Svátek",IFERROR(INDEX(SVATKY_2027!$C$5:$C$22,MATCH($A33,SVATKY_2027!$B$5:$B$22,0)),""),"") | U33: =IF($A33="","",IF(WEEKDAY($A33,2)>5,"Víkend",IF(COUNTIF(SVATKY_2027!$B$5:$B$22,$A33)>0,"Svátek",""))) | V33: =IF(OR($A33="",$U33="Víkend"),0,IF($U33="Svátek",1,MIN(1,COUNTIF($K33:$P33,"x")+COUNTIF($K33:$P33,1)+0.5*COUNTIF($K33:$P33,0.5)+IF(OR($R33="x",$R33=1),1,IF($R33=0.5,0.5,0))))) -> 0
A34: =IF(MONTH(DATE(PREDVOLBY!$C$8,1,29))=1,DATE(PREDVOLBY!$C$8,1,29),"") -> 46416 | B34: =IF($A34="","",CHOOSE(WEEKDAY($A34,2),"po","út","st","čt","pá","so","ne")) -> pá | C34: =IF(OR($A34="",$U34="Víkend"),"",IF($V34>=1,"-",PREDVOLBY!$C$18)) -> 0.3125 | D34: =IF(OR($A34="",$U34="Víkend"),"",IF($V34>=1,"-",PREDVOLBY!$C$19)) -> 0.47916667 | E34: =IF(OR($A34="",$U34="Víkend"),"",IF($V34>=0.5,"-",PREDVOLBY!$C$20)) -> 0.5 | F34: =IF(OR($A34="",$U34="Víkend"),"",IF($V34>=0.5,"-",PREDVOLBY!$C$21)) -> 0.66666667 | G34: =IF(OR($A34="",$U34="Víkend"),"",IF(ISNUMBER($C34)+ISNUMBER($E34)=0,"-",ROUND((IF(ISNUMBER($C34),$D34-$C34,0)+IF(ISNUMBER($E34),$F34-$E34,0))*24,2))) -> 8 | H34: =IF($G34="","",IF(ISNUMBER($G34),MAX(0,ROUND($G34-PREDVOLBY!$C$22*(1-$V34),2)),"-")) -> 0 | I34: =IF($G34="","",IF(AND(ISNUMBER($G34),$J34=""),IF($G34>=PREDVOLBY!$C$26,PREDVOLBY!$C$25,"-"),"-")) -> 129.5 | M34: =IF($U34="Svátek",1,"") | S34: =IF($U34="Svátek",IFERROR(INDEX(SVATKY_2027!$C$5:$C$22,MATCH($A34,SVATKY_2027!$B$5:$B$22,0)),""),"") | U34: =IF($A34="","",IF(WEEKDAY($A34,2)>5,"Víkend",IF(COUNTIF(SVATKY_2027!$B$5:$B$22,$A34)>0,"Svátek",""))) | V34: =IF(OR($A34="",$U34="Víkend"),0,IF($U34="Svátek",1,MIN(1,COUNTIF($K34:$P34,"x")+COUNTIF($K34:$P34,1)+0.5*COUNTIF($K34:$P34,0.5)+IF(OR($R34="x",$R34=1),1,IF($R34=0.5,0.5,0))))) -> 0
A35: =IF(MONTH(DATE(PREDVOLBY!$C$8,1,30))=1,DATE(PREDVOLBY!$C$8,1,30),"") -> 46417 | B35: =IF($A35="","",CHOOSE(WEEKDAY($A35,2),"po","út","st","čt","pá","so","ne")) -> so | C35: =IF(OR($A35="",$U35="Víkend"),"",IF($V35>=1,"-",PREDVOLBY!$C$18)) | D35: =IF(OR($A35="",$U35="Víkend"),"",IF($V35>=1,"-",PREDVOLBY!$C$19)) | E35: =IF(OR($A35="",$U35="Víkend"),"",IF($V35>=0.5,"-",PREDVOLBY!$C$20)) | F35: =IF(OR($A35="",$U35="Víkend"),"",IF($V35>=0.5,"-",PREDVOLBY!$C$21)) | G35: =IF(OR($A35="",$U35="Víkend"),"",IF(ISNUMBER($C35)+ISNUMBER($E35)=0,"-",ROUND((IF(ISNUMBER($C35),$D35-$C35,0)+IF(ISNUMBER($E35),$F35-$E35,0))*24,2))) | H35: =IF($G35="","",IF(ISNUMBER($G35),MAX(0,ROUND($G35-PREDVOLBY!$C$22*(1-$V35),2)),"-")) | I35: =IF($G35="","",IF(AND(ISNUMBER($G35),$J35=""),IF($G35>=PREDVOLBY!$C$26,PREDVOLBY!$C$25,"-"),"-")) | M35: =IF($U35="Svátek",1,"") | S35: =IF($U35="Svátek",IFERROR(INDEX(SVATKY_2027!$C$5:$C$22,MATCH($A35,SVATKY_2027!$B$5:$B$22,0)),""),"") | U35: =IF($A35="","",IF(WEEKDAY($A35,2)>5,"Víkend",IF(COUNTIF(SVATKY_2027!$B$5:$B$22,$A35)>0,"Svátek",""))) -> Víkend | V35: =IF(OR($A35="",$U35="Víkend"),0,IF($U35="Svátek",1,MIN(1,COUNTIF($K35:$P35,"x")+COUNTIF($K35:$P35,1)+0.5*COUNTIF($K35:$P35,0.5)+IF(OR($R35="x",$R35=1),1,IF($R35=0.5,0.5,0))))) -> 0
A36: =IF(MONTH(DATE(PREDVOLBY!$C$8,1,31))=1,DATE(PREDVOLBY!$C$8,1,31),"") -> 46418 | B36: =IF($A36="","",CHOOSE(WEEKDAY($A36,2),"po","út","st","čt","pá","so","ne")) -> ne | C36: =IF(OR($A36="",$U36="Víkend"),"",IF($V36>=1,"-",PREDVOLBY!$C$18)) | D36: =IF(OR($A36="",$U36="Víkend"),"",IF($V36>=1,"-",PREDVOLBY!$C$19)) | E36: =IF(OR($A36="",$U36="Víkend"),"",IF($V36>=0.5,"-",PREDVOLBY!$C$20)) | F36: =IF(OR($A36="",$U36="Víkend"),"",IF($V36>=0.5,"-",PREDVOLBY!$C$21)) | G36: =IF(OR($A36="",$U36="Víkend"),"",IF(ISNUMBER($C36)+ISNUMBER($E36)=0,"-",ROUND((IF(ISNUMBER($C36),$D36-$C36,0)+IF(ISNUMBER($E36),$F36-$E36,0))*24,2))) | H36: =IF($G36="","",IF(ISNUMBER($G36),MAX(0,ROUND($G36-PREDVOLBY!$C$22*(1-$V36),2)),"-")) | I36: =IF($G36="","",IF(AND(ISNUMBER($G36),$J36=""),IF($G36>=PREDVOLBY!$C$26,PREDVOLBY!$C$25,"-"),"-")) | M36: =IF($U36="Svátek",1,"") | S36: =IF($U36="Svátek",IFERROR(INDEX(SVATKY_2027!$C$5:$C$22,MATCH($A36,SVATKY_2027!$B$5:$B$22,0)),""),"") | U36: =IF($A36="","",IF(WEEKDAY($A36,2)>5,"Víkend",IF(COUNTIF(SVATKY_2027!$B$5:$B$22,$A36)>0,"Svátek",""))) -> Víkend | V36: =IF(OR($A36="",$U36="Víkend"),0,IF($U36="Svátek",1,MIN(1,COUNTIF($K36:$P36,"x")+COUNTIF($K36:$P36,1)+0.5*COUNTIF($K36:$P36,0.5)+IF(OR($R36="x",$R36=1),1,IF($R36=0.5,0.5,0))))) -> 0
A37: CELKEM ZA MĚSÍC | G37: =SUM(G6:G36) -> 160 | H37: =SUM(H6:H36) -> 0 | I37: =SUM(I6:I36) -> 2590 | J37: =COUNTA(J6:J36) -> 0 | K37: =SUM(K6:K36)+COUNTIF(K6:K36,"x") -> 0 | L37: =SUM(L6:L36)+COUNTIF(L6:L36,"x") -> 0 | M37: =SUM(M6:M36)+COUNTIF(M6:M36,"x") -> 1 | N37: =SUM(N6:N36)+COUNTIF(N6:N36,"x") -> 0 | O37: =SUM(O6:O36)+COUNTIF(O6:O36,"x") -> 0 | P37: =SUM(P6:P36)+COUNTIF(P6:P36,"x") -> 0 | Q37: =SUM(Q6:Q36)+COUNTIF(Q6:Q36,"x") -> 0 | R37: =SUM(R6:R36)+COUNTIF(R6:R36,"x") -> 0
A38: Stravenky (ks) | D38: =COUNT(I6:I36) -> 20 | F38: ="Nárok na stravné po odpracování "&PREDVOLBY!$C$26&" hodin" -> Nárok na stravné po odpracování 3 hodin | M38: Cestovní účet:
A42: Podpis zaměstnance: | J42: Podpis vedoucího:
A46: D – dovolená, N – nemoc, S – státní svátek (doplní se automaticky), § – překážky v práci s náhradou mzdy (lékař, ošetření člena rodiny, darování krve, svatba, pohřeb, volno dle sociálního programu apod.), NV – náhradní volno, NEP – neplacené volno. Do sloupců D–NEP, Home Office a Sick Day zadávejte 1 (celý den), 0,5 (půl dne) nebo x. Víkendy a svátky se vyplní samy.
...

Sheet 02_2027
A1: EVIDENCE PRACOVNÍ DOBY 2027 | N1: Dodio · správa firemních absencí na pár kliknutí
A2: =IF(PREDVOLBY!$C$7="","",PREDVOLBY!$C$7) -> Název společnosti
A3: OBDOBÍ | C3: Únor 2027 | G3: JMÉNO: | I3: =IF(OR(PREDVOLBY!$C$6="",PREDVOLBY!$C$6="Jméno a příjmení"),"DOPLŇTE ÚDAJE V KARTĚ PŘEDVOLBY",PREDVOLBY!$C$6) -> DOPLŇTE ÚDAJE V KARTĚ PŘEDVOLBY | U3: 46419
A4: Den | B4: dne | C4: pracovní doba | E4: pracovní doba | G4: odpracováno celkem (h) | H4: z toho přesčas (h) | I4: stravné (Kč) | J4: SC / pracovní oběd / TMB | K4: neodpracované hodiny z důvodu | Q4: Home Office | R4: Sick Day | S4: Poznámka | U4: pomocné sloupce (skryté)
C5: od | D5: do | E5: od | F5: do | K5: D | L5: N | M5: S | N5: § | O5: NV | P5: NEP | U5: typ dne | V5: podíl nepřítomnosti
A6: =IF(MONTH(DATE(PREDVOLBY!$C$8,2,1))=2,DATE(PREDVOLBY!$C$8,2,1),"") -> 46419 | B6: =IF($A6="","",CHOOSE(WEEKDAY($A6,2),"po","út","st","čt","pá","so","ne")) -> po | C6: =IF(OR($A6="",$U6="Víkend"),"",IF($V6>=1,"-",PREDVOLBY!$C$18)) -> 0.3125 | D6: =IF(OR($A6="",$U6="Víkend"),"",IF($V6>=1,"-",PREDVOLBY!$C$19)) -> 0.47916667 | E6: =IF(OR($A6="",$U6="Víkend"),"",IF($V6>=0.5,"-",PREDVOLBY!$C$20)) -> 0.5 | F6: =IF(OR($A6="",$U6="Víkend"),"",IF($V6>=0.5,"-",PREDVOLBY!$C$21)) -> 0.66666667 | G6: =IF(OR($A6="",$U6="Víkend"),"",IF(ISNUMBER($C6)+ISNUMBER($E6)=0,"-",ROUND((IF(ISNUMBER($C6),$D6-$C6,0)+IF(ISNUMBER($E6),$F6-$E6,0))*24,2))) -> 8 | H6: =IF($G6="","",IF(ISNUMBER($G6),MAX(0,ROUND($G6-PREDVOLBY!$C$22*(1-$V6),2)),"-")) -> 0 | I6: =IF($G6="","",IF(AND(ISNUMBER($G6),$J6=""),IF($G6>=PREDVOLBY!$C$26,PREDVOLBY!$C$25,"-"),"-")) -> 129.5 | M6: =IF($U6="Svátek",1,"") | S6: =IF($U6="Svátek",IFERROR(INDEX(SVATKY_2027!$C$5:$C$22,MATCH($A6,SVATKY_2027!$B$5:$B$22,0)),""),"") | U6: =IF($A6="","",IF(WEEKDAY($A6,2)>5,"Víkend",IF(COUNTIF(SVATKY_2027!$B$5:$B$22,$A6)>0,"Svátek",""))) | V6: =IF(OR($A6="",$U6="Víkend"),0,IF($U6="Svátek",1,MIN(1,COUNTIF($K6:$P6,"x")+COUNTIF($K6:$P6,1)+0.5*COUNTIF($K6:$P6,0.5)+IF(OR($R6="x",$R6=1),1,IF($R6=0.5,0.5,0))))) -> 0
A7: =IF(MONTH(DATE(PREDVOLBY!$C$8,2,2))=2,DATE(PREDVOLBY!$C$8,2,2),"") -> 46420 | B7: =IF($A7="","",CHOOSE(WEEKDAY($A7,2),"po","út","st","čt","pá","so","ne")) -> út | C7: =IF(OR($A7="",$U7="Víkend"),"",IF($V7>=1,"-",PREDVOLBY!$C$18)) -> 0.3125 | D7: =IF(OR($A7="",$U7="Víkend"),"",IF($V7>=1,"-",PREDVOLBY!$C$19)) -> 0.47916667 | E7: =IF(OR($A7="",$U7="Víkend"),"",IF($V7>=0.5,"-",PREDVOLBY!$C$20)) -> 0.5 | F7: =IF(OR($A7="",$U7="Víkend"),"",IF($V7>=0.5,"-",PREDVOLBY!$C$21)) -> 0.66666667 | G7: =IF(OR($A7="",$U7="Víkend"),"",IF(ISNUMBER($C7)+ISNUMBER($E7)=0,"-",ROUND((IF(ISNUMBER($C7),$D7-$C7,0)+IF(ISNUMBER($E7),$F7-$E7,0))*24,2))) -> 8 | H7: =IF($G7="","",IF(ISNUMBER($G7),MAX(0,ROUND($G7-PREDVOLBY!$C$22*(1-$V7),2)),"-")) -> 0 | I7: =IF($G7="","",IF(AND(ISNUMBER($G7),$J7=""),IF($G7>=PREDVOLBY!$C$26,PREDVOLBY!$C$25,"-"),"-")) -> 129.5 | M7: =IF($U7="Svátek",1,"") | S7: =IF($U7="Svátek",IFERROR(INDEX(SVATKY_2027!$C$5:$C$22,MATCH($A7,SVATKY_2027!$B$5:$B$22,0)),""),"") | U7: =IF($A7="","",IF(WEEKDAY($A7,2)>5,"Víkend",IF(COUNTIF(SVATKY_2027!$B$5:$B$22,$A7)>0,"Svátek",""))) | V7: =IF(OR($A7="",$U7="Víkend"),0,IF($U7="Svátek",1,MIN(1,COUNTIF($K7:$P7,"x")+COUNTIF($K7:$P7,1)+0.5*COUNTIF($K7:$P7,0.5)+IF(OR($R7="x",$R7=1),1,IF($R7=0.5,0.5,0))))) -> 0
A8: =IF(MONTH(DATE(PREDVOLBY!$C$8,2,3))=2,DATE(PREDVOLBY!$C$8,2,3),"") -> 46421 | B8: =IF($A8="","",CHOOSE(WEEKDAY($A8,2),"po","út","st","čt","pá","so","ne")) -> st | C8: =IF(OR($A8="",$U8="Víkend"),"",IF($V8>=1,"-",PREDVOLBY!$C$18)) -> 0.3125 | D8: =IF(OR($A8="",$U8="Víkend"),"",IF($V8>=1,"-",PREDVOLBY!$C$19)) -> 0.47916667 | E8: =IF(OR($A8="",$U8="Víkend"),"",IF($V8>=0.5,"-",PREDVOLBY!$C$20)) -> 0.5 | F8: =IF(OR($A8="",$U8="Víkend"),"",IF($V8>=0.5,"-",PREDVOLBY!$C$21)) -> 0.66666667 | G8: =IF(OR($A8="",$U8="Víkend"),"",IF(ISNUMBER($C8)+ISNUMBER($E8)=0,"-",ROUND((IF(ISNUMBER($C8),$D8-$C8,0)+IF(ISNUMBER($E8),$F8-$E8,0))*24,2))) -> 8 | H8: =IF($G8="","",IF(ISNUMBER($G8),MAX(0,ROUND($G8-PREDVOLBY!$C$22*(1-$V8),2)),"-")) -> 0 | I8: =IF($G8="","",IF(AND(ISNUMBER($G8),$J8=""),IF($G8>=PREDVOLBY!$C$26,PREDVOLBY!$C$25,"-"),"-")) -> 129.5 | M8: =IF($U8="Svátek",1,"") | S8: =IF($U8="Svátek",IFERROR(INDEX(SVATKY_2027!$C$5:$C$22,MATCH($A8,SVATKY_2027!$B$5:$B$22,0)),""),"") | U8: =IF($A8="","",IF(WEEKDAY($A8,2)>5,"Víkend",IF(COUNTIF(SVATKY_2027!$B$5:$B$22,$A8)>0,"Svátek",""))) | V8: =IF(OR($A8="",$U8="Víkend"),0,IF($U8="Svátek",1,MIN(1,COUNTIF($K8:$P8,"x")+COUNTIF($K8:$P8,1)+0.5*COUNTIF($K8:$P8,0.5)+IF(OR($R8="x",$R8=1),1,IF($R8=0.5,0.5,0))))) -> 0
A9: =IF(MONTH(DATE(PREDVOLBY!$C$8,2,4))=2,DATE(PREDVOLBY!$C$8,2,4),"") -> 46422 | B9: =IF($A9="","",CHOOSE(WEEKDAY($A9,2),"po","út","st","čt","pá","so","ne")) -> čt | C9: =IF(OR($A9="",$U9="Víkend"),"",IF($V9>=1,"-",PREDVOLBY!$C$18)) -> 0.3125 | D9: =IF(OR($A9="",$U9="Víkend"),"",IF($V9>=1,"-",PREDVOLBY!$C$19)) -> 0.47916667 | E9: =IF(OR($A9="",$U9="Víkend"),"",IF($V9>=0.5,"-",PREDVOLBY!$C$20)) -> 0.5 | F9: =IF(OR($A9="",$U9="Víkend"),"",IF($V9>=0.5,"-",PREDVOLBY!$C$21)) -> 0.66666667 | G9: =IF(OR($A9="",$U9="Víkend"),"",IF(ISNUMBER($C9)+ISNUMBER($E9)=0,"-",ROUND((IF(ISNUMBER($C9),$D9-$C9,0)+IF(ISNUMBER($E9),$F9-$E9,0))*24,2))) -> 8 | H9: =IF($G9="","",IF(ISNUMBER($G9),MAX(0,ROUND($G9-PREDVOLBY!$C$22*(1-$V9),2)),"-")) -> 0 | I9: =IF($G9="","",IF(AND(ISNUMBER($G9),$J9=""),IF($G9>=PREDVOLBY!$C$26,PREDVOLBY!$C$25,"-"),"-")) -> 129.5 | M9: =IF($U9="Svátek",1,"") | S9: =IF($U9="Svátek",IFERROR(INDEX(SVATKY_2027!$C$5:$C$22,MATCH($A9,SVATKY_2027!$B$5:$B$22,0)),""),"") | U9: =IF($A9="","",IF(WEEKDAY($A9,2)>5,"Víkend",IF(COUNTIF(SVATKY_2027!$B$5:$B$22,$A9)>0,"Svátek",""))) | V9: =IF(OR($A9="",$U9="Víkend"),0,IF($U9="Svátek",1,MIN(1,COUNTIF($K9:$P9,"x")+COUNTIF($K9:$P9,1)+0.5*COUNTIF($K9:$P9,0.5)+IF(OR($R9="x",$R9=1),1,IF($R9=0.5,0.5,0))))) -> 0
A10: =IF(MONTH(DATE(PREDVOLBY!$C$8,2,5))=2,DATE(PREDVOLBY!$C$8,2,5),"") -> 46423 | B10: =IF($A10="","",CHOOSE(WEEKDAY($A10,2),"po","út","st","čt","pá","so","ne")) -> pá | C10: =IF(OR($A10="",$U10="Víkend"),"",IF($V10>=1,"-",PREDVOLBY!$C$18)) -> 0.3125 | D10: =IF(OR($A10="",$U10="Víkend"),"",IF($V10>=1,"-",PREDVOLBY!$C$19)) -> 0.47916667 | E10: =IF(OR($A10="",$U10="Víkend"),"",IF($V10>=0.5,"-",PREDVOLBY!$C$20)) -> 0.5 | F10: =IF(OR($A10="",$U10="Víkend"),"",IF($V10>=0.5,"-",PREDVOLBY!$C$21)) -> 0.66666667 | G10: =IF(OR($A10="",$U10="Víkend"),"",IF(ISNUMBER($C10)+ISNUMBER($E10)=0,"-",ROUND((IF(ISNUMBER($C10),$D10-$C10,0)+IF(ISNUMBER($E10),$F10-$E10,0))*24,2))) -> 8 | H10: =IF($G10="","",IF(ISNUMBER($G10),MAX(0,ROUND($G10-PREDVOLBY!$C$22*(1-$V10),2)),"-")) -> 0 | I10: =IF($G10="","",IF(AND(ISNUMBER($G10),$J10=""),IF($G10>=PREDVOLBY!$C$26,PREDVOLBY!$C$25,"-"),"-")) -> 129.5 | M10: =IF($U10="Svátek",1,"") | S10: =IF($U10="Svátek",IFERROR(INDEX(SVATKY_2027!$C$5:$C$22,MATCH($A10,SVATKY_2027!$B$5:$B$22,0)),""),"") | U10: =IF($A10="","",IF(WEEKDAY($A10,2)>5,"Víkend",IF(COUNTIF(SVATKY_2027!$B$5:$B$22,$A10)>0,"Svátek",""))) | V10: =IF(OR($A10="",$U10="Víkend"),0,IF($U10="Svátek",1,MIN(1,COUNTIF($K10:$P10,"x")+COUNTIF($K10:$P10,1)+0.5*COUNTIF($K10:$P10,0.5)+IF(OR($R10="x",$R10=1),1,IF($R10=0.5,0.5,0))))) -> 0
A11: =IF(MONTH(DATE(PREDVOLBY!$C$8,2,6))=2,DATE(PREDVOLBY!$C$8,2,6),"") -> 46424 | B11: =IF($A11="","",CHOOSE(WEEKDAY($A11,2),"po","út","st","čt","pá","so","ne")) -> so | C11: =IF(OR($A11="",$U11="Víkend"),"",IF($V11>=1,"-",PREDVOLBY!$C$18)) | D11: =IF(OR($A11="",$U11="Víkend"),"",IF($V11>=1,"-",PREDVOLBY!$C$19)) | E11: =IF(OR($A11="",$U11="Víkend"),"",IF($V11>=0.5,"-",PREDVOLBY!$C$20)) | F11: =IF(OR($A11="",$U11="Víkend"),"",IF($V11>=0.5,"-",PREDVOLBY!$C$21)) | G11: =IF(OR($A11="",$U11="Víkend"),"",IF(ISNUMBER($C11)+ISNUMBER($E11)=0,"-",ROUND((IF(ISNUMBER($C11),$D11-$C11,0)+IF(ISNUMBER($E11),$F11-$E11,0))*24,2))) | H11: =IF($G11="","",IF(ISNUMBER($G11),MAX(0,ROUND($G11-PREDVOLBY!$C$22*(1-$V11),2)),"-")) | I11: =IF($G11="","",IF(AND(ISNUMBER($G11),$J11=""),IF($G11>=PREDVOLBY!$C$26,PREDVOLBY!$C$25,"-"),"-")) | M11: =IF($U11="Svátek",1,"") | S11: =IF($U11="Svátek",IFERROR(INDEX(SVATKY_2027!$C$5:$C$22,MATCH($A11,SVATKY_2027!$B$5:$B$22,0)),""),"") | U11: =IF($A11="","",IF(WEEKDAY($A11,2)>5,"Víkend",IF(COUNTIF(SVATKY_2027!$B$5:$B$22,$A11)>0,"Svátek",""))) -> Víkend | V11: =IF(OR($A11="",$U11="Víkend"),0,IF($U11="Svátek",1,MIN(1,COUNTIF($K11:$P11,"x")+COUNTIF($K11:$P11,1)+0.5*COUNTIF($K11:$P11,0.5)+IF(OR($R11="x",$R11=1),1,IF($R11=0.5,0.5,0))))) -> 0
A12: =IF(MONTH(DATE(PREDVOLBY!$C$8,2,7))=2,DATE(PREDVOLBY!$C$8,2,7),"") -> 46425 | B12: =IF($A12="","",CHOOSE(WEEKDAY($A12,2),"po","út","st","čt","pá","so","ne")) -> ne | C12: =IF(OR($A12="",$U12="Víkend"),"",IF($V12>=1,"-",PREDVOLBY!$C$18)) | D12: =IF(OR($A12="",$U12="Víkend"),"",IF($V12>=1,"-",PREDVOLBY!$C$19)) | E12: =IF(OR($A12="",$U12="Víkend"),"",IF($V12>=0.5,"-",PREDVOLBY!$C$20)) | F12: =IF(OR($A12="",$U12="Víkend"),"",IF($V12>=0.5,"-",PREDVOLBY!$C$21)) | G12: =IF(OR($A12="",$U12="Víkend"),"",IF(ISNUMBER($C12)+ISNUMBER($E12)=0,"-",ROUND((IF(ISNUMBER($C12),$D12-$C12,0)+IF(ISNUMBER($E12),$F12-$E12,0))*24,2))) | H12: =IF($G12="","",IF(ISNUMBER($G12),MAX(0,ROUND($G12-PREDVOLBY!$C$22*(1-$V12),2)),"-")) | I12: =IF($G12="","",IF(AND(ISNUMBER($G12),$J12=""),IF($G12>=PREDVOLBY!$C$26,PREDVOLBY!$C$25,"-"),"-")) | M12: =IF($U12="Svátek",1,"") | S12: =IF($U12="Svátek",IFERROR(INDEX(SVATKY_2027!$C$5:$C$22,MATCH($A12,SVATKY_2027!$B$5:$B$22,0)),""),"") | U12: =IF($A12="","",IF(WEEKDAY($A12,2)>5,"Víkend",IF(COUNTIF(SVATKY_2027!$B$5:$B$22,$A12)>0,"Svátek",""))) -> Víkend | V12: =IF(OR($A12="",$U12="Víkend"),0,IF($U12="Svátek",1,MIN(1,COUNTIF($K12:$P12,"x")+COUNTIF($K12:$P12,1)+0.5*COUNTIF($K12:$P12,0.5)+IF(OR($R12="x",$R12=1),1,IF($R12=0.5,0.5,0))))) -> 0
A13: =IF(MONTH(DATE(PREDVOLBY!$C$8,2,8))=2,DATE(PREDVOLBY!$C$8,2,8),"") -> 46426 | B13: =IF($A13="","",CHOOSE(WEEKDAY($A13,2),"po","út","st","čt","pá","so","ne")) -> po | C13: =IF(OR($A13="",$U13="Víkend"),"",IF($V13>=1,"-",PREDVOLBY!$C$18)) -> 0.3125 | D13: =IF(OR($A13="",$U13="Víkend"),"",IF($V13>=1,"-",PREDVOLBY!$C$19)) -> 0.47916667 | E13: =IF(OR($A13="",$U13="Víkend"),"",IF($V13>=0.5,"-",PREDVOLBY!$C$20)) -> 0.5 | F13: =IF(OR($A13="",$U13="Víkend"),"",IF($V13>=0.5,"-",PREDVOLBY!$C$21)) -> 0.66666667 | G13: =IF(OR($A13="",$U13="Víkend"),"",IF(ISNUMBER($C13)+ISNUMBER($E13)=0,"-",ROUND((IF(ISNUMBER($C13),$D13-$C13,0)+IF(ISNUMBER($E13),$F13-$E13,0))*24,2))) -> 8 | H13: =IF($G13="","",IF(ISNUMBER($G13),MAX(0,ROUND($G13-PREDVOLBY!$C$22*(1-$V13),2)),"-")) -> 0 | I13: =IF($G13="","",IF(AND(ISNUMBER($G13),$J13=""),IF($G13>=PREDVOLBY!$C$26,PREDVOLBY!$C$25,"-"),"-")) -> 129.5 | M13: =IF($U13="Svátek",1,"") | S13: =IF($U13="Svátek",IFERROR(INDEX(SVATKY_2027!$C$5:$C$22,MATCH($A13,SVATKY_2027!$B$5:$B$22,0)),""),"") | U13: =IF($A13="","",IF(WEEKDAY($A13,2)>5,"Víkend",IF(COUNTIF(SVATKY_2027!$B$5:$B$22,$A13)>0,"Svátek",""))) | V13: =IF(OR($A13="",$U13="Víkend"),0,IF($U13="Svátek",1,MIN(1,COUNTIF($K13:$P13,"x")+COUNTIF($K13:$P13,1)+0.5*COUNTIF($K13:$P13,0.5)+IF(OR($R13="x",$R13=1),1,IF($R13=0.5,0.5,0))))) -> 0
A14: =IF(MONTH(DATE(PREDVOLBY!$C$8,2,9))=2,DATE(PREDVOLBY!$C$8,2,9),"") -> 46427 | B14: =IF($A14="","",CHOOSE(WEEKDAY($A14,2),"po","út","st","čt","pá","so","ne")) -> út | C14: =IF(OR($A14="",$U14="Víkend"),"",IF($V14>=1,"-",PREDVOLBY!$C$18)) -> 0.3125 | D14: =IF(OR($A14="",$U14="Víkend"),"",IF($V14>=1,"-",PREDVOLBY!$C$19)) -> 0.47916667 | E14: =IF(OR($A14="",$U14="Víkend"),"",IF($V14>=0.5,"-",PREDVOLBY!$C$20)) -> 0.5 | F14: =IF(OR($A14="",$U14="Víkend"),"",IF($V14>=0.5,"-",PREDVOLBY!$C$21)) -> 0.66666667 | G14: =IF(OR($A14="",$U14="Víkend"),"",IF(ISNUMBER($C14)+ISNUMBER($E14)=0,"-",ROUND((IF(ISNUMBER($C14),$D14-$C14,0)+IF(ISNUMBER($E14),$F14-$E14,0))*24,2))) -> 8 | H14: =IF($G14="","",IF(ISNUMBER($G14),MAX(0,ROUND($G14-PREDVOLBY!$C$22*(1-$V14),2)),"-")) -> 0 | I14: =IF($G14="","",IF(AND(ISNUMBER($G14),$J14=""),IF($G14>=PREDVOLBY!$C$26,PREDVOLBY!$C$25,"-"),"-")) -> 129.5 | M14: =IF($U14="Svátek",1,"") | S14: =IF($U14="Svátek",IFERROR(INDEX(SVATKY_2027!$C$5:$C$22,MATCH($A14,SVATKY_2027!$B$5:$B$22,0)),""),"") | U14: =IF($A14="","",IF(WEEKDAY($A14,2)>5,"Víkend",IF(COUNTIF(SVATKY_2027!$B$5:$B$22,$A14)>0,"Svátek",""))) | V14: =IF(OR($A14="",$U14="Víkend"),0,IF($U14="Svátek",1,MIN(1,COUNTIF($K14:$P14,"x")+COUNTIF($K14:$P14,1)+0.5*COUNTIF($K14:$P14,0.5)+IF(OR($R14="x",$R14=1),1,IF($R14=0.5,0.5,0))))) -> 0
